Workbook

Sheet Sem1-2
A1: ຜົນການຮຽນສົກຮຽນ2022 - 2023 ນັກສຶກສາຮຸ່ນທີ19 ພາກວິຊາພາສາຍີ່ປຸ່ນ | AN1: ຜົນການຮຽນສົກຮຽນ2022 - 2023 ນັກສຶກສາຮຸ່ນທີ 20 ພາກວິຊາພາສາຍີ່ປຸ່ນ
A2: ລ/ດ | B2: ລະຫັດນສ | C2: ເພດ | D2: ຊື່ພາສາລາວ | E2: ນາມສະກຸນພາສາລາວ | F2: ຊື່ພາສາອັງກິດ | G2: ນາມສະກຸນພາສາອັງກິດ | H2: ວ.ດ.ປີເກີດ | I2: ແຂວງເກີດ | J2: ຫ້ອງ | K2: ພາກຮຽນທີ 1 (17 ໜ່ວຍກິດ) | AL2: GPA (ພາກຮຽນ 1) | AN2: ຄ່າລະດັບ | AO2: ລະດັບ | AP2: ຄະແນນລວມ | AQ2: ຄ່າລະດັບ | AR2: ລະດັບ | AS2: ຄະແນນລວມ | AT2: ຄ່າລະດັບ | AU2: ລະດັບ | AV2: ຄະແນນລວມ | AW2: ພາກຮຽນທີ2(16ໜ່ວຍກິດ) | BX2: GPA | BY2: CGPA | BZ2: Rank | CA2: ໝາຍເຫດ
K3: ພາສາຍີ່ປຸ່ນ 1 (3) | N3: ໄວຍາກອນຍີ່ປຸ່ນ 1 (2) | Q3: ຄັນຈິ 1 (1) | T3: ຟັງ-ເວົ້າພາສາຍີ່ປຸ່ນ 1 (2) | W3: ສຽງ-ຕົວອັກສອນ (1) | Z3: ພາສາອັງກິດ 1 (2) | AC3: ລາວສຶກສາ1 (2) | AF3: ຈິດຕະວິທະຍາທົ່ວໄປ (2) | AI3: ທັກສະພື້ນຖານການນຳໃຊ້ຂໍ້ມູນຂ່າວສານເທັກໂນໂລຊີ (2) | AW3: ພາສາຍີ່ປຸ່ນ2(3) | AZ3: ການຟັງ-ການເວົ້າພາສາຍີ່ປຸ່ນ2 (2) | BC3: ຄັນຈິ2(1) | BF3: ໄວຍາກອນ2(2) | BI3: ການອ່ານພາສາຍີ່ປຸ່ນ1(1) | BL3: ການຂຽນພາສາຍີ່ປຸ່ນ1(1) | BO3: ຄອມພິວເຕີ(2) | BR3: ລາວສຶກສາ2(2) | BU3: ການເມືອງ(2)
K4: ຄະແນນລວມ | L4: ຄ່າລະດັບ | M4: ລະດັບ | N4: ຄະແນນລວມ | O4: ຄ່າລະດັບ | P4: ລະດັບ | Q4: ຄະແນນລວມ | R4: ຄ່າລະດັບ | S4: ລະດັບ | T4: ຄະແນນລວມ | U4: ຄ່າລະດັບ | V4: ລະດັບ | W4: ຄະແນນລວມ | X4: ຄ່າລະດັບ | Y4: ລະດັບ | Z4: ຄະແນນລວມ | AA4: ຄ່າລະດັບ | AB4: ລະດັບ | AC4: ຄະແນນລວມ | AD4: ຄ່າລະດັບ | AE4: ລະດັບ | AF4: ຄະແນນລວມ | AG4: ຄ່າລະດັບ | AH4: ລະດັບ | AI4: ຄະແນນລວມ | AJ4: ຄ່າລະດັບ | AK4: ລະດັບ | AW4: ຄ່າລະດັບ | AX4: ລະດັບ | AY4: ຄະແນນລວມ | AZ4: ຄ່າລະດັບ | BA4: ລະດັບ | BB4: ຄະແນນລວມ | BC4: ຄ່າລະດັບ | BD4: ລະດັບ | BE4: ຄະແນນລວມ | BF4: ຄ່າລະດັບ | BG4: ລະດັບ | BH4: ຄະແນນລວມ | BI4: ຄ່າລະດັບ | BJ4: ລະດັບ | BK4: ຄະແນນລວມ | BL4: ຄ່າລະດັບ | BM4: ລະດັບ | BN4: ຄະແນນລວມ | BO4: ຄ່າລະດັບ | BP4: ລະດັບ | BQ4: GPA (ພາກຮຽນ 2) | BR4: ຄະແນນລວມ | BS4: ຄ່າລະດັບ | BT4: ລະດັບ | BU4: ຄະແນນລວມ | BV4: ຄ່າລະດັບ | BW4: ລະດັບ
AM5: ພາສາຍີ່ປຸ່ນ 2 (3)
AM6: ຄະແນນລວມ
A7: 1 | B7: 125Q0007/23 | C7: ທ້າວ | D7: ວາຍຸ | E7: ສິງຫາລາດ | F7: Mr.Vayou | G7: SINGHALATH | H7: 27/09/2005 | I7: ນະຄອນຫຼວງວຽງຈັນ | J7: 1 | K7: 87 | L7: =IF(K7>=91, 4.00, IF(K7>=81, 3.50, IF(K7>=70, 3.00, IF(K7>=65, 2.50, IF(K7>=60, 2.00, IF(K7>=55, 1.50, IF(K7>=50, 1.00, 0.00))))))) | M7: =IF(K7>=91,"A",IF(K7>=81,"B+",IF(K7>=70,"B",IF(K7>=65,"C+",IF(K7>=60,"C",IF(K7>=55,"D+",IF(K7>=50,"D","F"))))))) | N7: 99 | O7: =IF(N7>=91, 4.00, IF(N7>=81, 3.50, IF(N7>=70, 3.00, IF(N7>=65, 2.50, IF(N7>=60, 2.00, IF(N7>=55, 1.50, IF(N7>=50, 1.00, 0.00))))))) | P7: =IF(N7>=91,"A",IF(N7>=81,"B+",IF(N7>=70,"B",IF(N7>=65,"C+",IF(N7>=60,"C",IF(N7>=55,"D+",IF(N7>=50,"D","F"))))))) | Q7: 98 | R7: =IF(Q7>=91, 4.00, IF(Q7>=81, 3.50, IF(Q7>=70, 3.00, IF(Q7>=65, 2.50, IF(Q7>=60, 2.00, IF(Q7>=55, 1.50, IF(Q7>=50, 1.00, 0.00))))))) | S7: =IF(Q7>=91,"A",IF(Q7>=81,"B+",IF(Q7>=70,"B",IF(Q7>=65,"C+",IF(Q7>=60,"C",IF(Q7>=55,"D+",IF(Q7>=50,"D","F"))))))) | T7: 80 | U7: =IF(T7>=91, 4.00, IF(T7>=81, 3.50, IF(T7>=70, 3.00, IF(T7>=65, 2.50, IF(T7>=60, 2.00, IF(T7>=55, 1.50, IF(T7>=50, 1.00, 0.00))))))) | V7: =IF(T7>=91,"A",IF(T7>=81,"B+",IF(T7>=70,"B",IF(T7>=65,"C+",IF(T7>=60,"C",IF(T7>=55,"D+",IF(T7>=50,"D","F"))))))) | W7: 77 | X7: =IF(W7>=91, 4.00, IF(W7>=81, 3.50, IF(W7>=70, 3.00, IF(W7>=65, 2.50, IF(W7>=60, 2.00, IF(W7>=55, 1.50, IF(W7>=50, 1.00, 0.00))))))) | Y7: =IF(W7>=91,"A",IF(W7>=81,"B+",IF(W7>=70,"B",IF(W7>=65,"C+",IF(W7>=60,"C",IF(W7>=55,"D+",IF(W7>=50,"D","F"))))))) | Z7: 90.52 | AA7: =IF(Z7>=91, 4.00, IF(Z7>=81, 3.50, IF(Z7>=70, 3.00, IF(Z7>=65, 2.50, IF(Z7>=60, 2.00, IF(Z7>=55, 1.50, IF(Z7>=50, 1.00, 0.00))))))) | AB7: =IF(Z7>=91,"A",IF(Z7>=81,"B+",IF(Z7>=70,"B",IF(Z7>=65,"C+",IF(Z7>=60,"C",IF(Z7>=55,"D+",IF(Z7>=50,"D","F"))))))) | AC7: 85.5 | AD7: =IF(AC7>=91, 4.00, IF(AC7>=81, 3.50, IF(AC7>=70, 3.00, IF(AC7>=65, 2.50, IF(AC7>=60, 2.00, IF(AC7>=55, 1.50, IF(AC7>=50, 1.00, 0.00))))))) | AE7: =IF(AC7>=91,"A",IF(AC7>=81,"B+",IF(AC7>=70,"B",IF(AC7>=65,"C+",IF(AC7>=60,"C",IF(AC7>=55,"D+",IF(AC7>=50,"D","F"))))))) | AF7: 81 | AG7: =IF(AF7>=91, 4.00, IF(AF7>=81, 3.50, IF(AF7>=70, 3.00, IF(AF7>=65, 2.50, IF(AF7>=60, 2.00, IF(AF7>=55, 1.50, IF(AF7>=50, 1.00, 0.00))))))) | AH7: =IF(AF7>=91,"A",IF(AF7>=81,"B+",IF(AF7>=70,"B",IF(AF7>=65,"C+",IF(AF7>=60,"C",IF(AF7>=55,"D+",IF(AF7>=50,"D","F"))))))) | AI7: 81 | AJ7: =IF(AI7>=91, 4.00, IF(AI7>=81, 3.50, IF(AI7>=70, 3.00, IF(AI7>=65, 2.50, IF(AI7>=60, 2.00, IF(AI7>=55, 1.50, IF(AI7>=50, 1.00, 0.00))))))) | AK7: =IF(AI7>=91,"A",IF(AI7>=81,"B+",IF(AI7>=70,"B",IF(AI7>=65,"C+",IF(AI7>=60,"C",IF(AI7>=55,"D+",IF(AI7>=50,"D","F"))))))) | AL7: =ROUND((L7*3+O7*2+R7*1+U7*2+X7*1+AA7*2+AD7*2+AG7*2+AJ7*2)/17, 2) | AM7: 93 | AN7: =IF(AM7>=91, 4.00, IF(AM7>=81, 3.50, IF(AM7>=70, 3.00, IF(AM7>=65, 2.50, IF(AM7>=60, 2.00, IF(AM7>=55, 1.50, IF(AM7>=50, 1.00, 0.00))))))) | AO7: =IF(AM7>=91,"A",IF(AM7>=81,"B+",IF(AM7>=70,"B",IF(AM7>=65,"C+",IF(AM7>=60,"C",IF(AM7>=55,"D+",IF(AM7>=50,"D","F"))))))) | AP7: ທ້າວ | AQ7: =IF(AP7>=91, 4.00, IF(AP7>=81, 3.50, IF(AP7>=70, 3.00, IF(AP7>=65, 2.50, IF(AP7>=60, 2.00, IF(AP7>=55, 1.50, IF(AP7>=50, 1.00, 0.00))))))) | AR7: =IF(AP7>=91,"A",IF(AP7>=81,"B+",IF(AP7>=70,"B",IF(AP7>=65,"C+",IF(AP7>=60,"C",IF(AP7>=55,"D+",IF(AP7>=50,"D","F"))))))) | AS7: Mr.Vayou | AT7: =IF(AS7>=91, 4.00, IF(AS7>=81, 3.50, IF(AS7>=70, 3.00, IF(AS7>=65, 2.50, IF(AS7>=60, 2.00, IF(AS7>=55, 1.50, IF(AS7>=50, 1.00, 0.00))))))) | AU7: =IF(AS7>=91,"A",IF(AS7>=81,"B+",IF(AS7>=70,"B",IF(AS7>=65,"C+",IF(AS7>=60,"C",IF(AS7>=55,"D+",IF(AS7>=50,"D","F"))))))) | AV7: ນະຄອນຫຼວງວຽງຈັນ | AW7: =IF(AV7>=91, 4.00, IF(AV7>=81, 3.50, IF(AV7>=70, 3.00, IF(AV7>=65, 2.50, IF(AV7>=60, 2.00, IF(AV7>=55, 1.50, IF(AV7>=50, 1.00, 0.00))))))) | AX7: =IF(AV7>=91,"A",IF(AV7>=81,"B+",IF(AV7>=70,"B",IF(AV7>=65,"C+",IF(AV7>=60,"C",IF(AV7>=55,"D+",IF(AV7>=50,"D","F"))))))) | AY7: =IF(AW7>90,"A",IF(AW7>80,"B+",IF(AW7>69,"B",IF(AW7>64,"C+",IF(AW7>59,"C",IF(AW7>54,"D+",IF(AW7>49,"D",IF(AW7>=0,"F")))))))) -> A | AZ7: =IF(AY7>=91, 4.00, IF(AY7>=81, 3.50, IF(AY7>=70, 3.00, IF(AY7>=65, 2.50, IF(AY7>=60, 2.00, IF(AY7>=55, 1.50, IF(AY7>=50, 1.00, 0.00))))))) | BA7: =IF(AY7>=91,"A",IF(AY7>=81,"B+",IF(AY7>=70,"B",IF(AY7>=65,"C+",IF(AY7>=60,"C",IF(AY7>=55,"D+",IF(AY7>=50,"D","F"))))))) | BB7: =IF(AZ7>90,"A",IF(AZ7>80,"B+",IF(AZ7>69,"B",IF(AZ7>64,"C+",IF(AZ7>59,"C",IF(AZ7>54,"D+",IF(AZ7>49,"D",IF(AZ7>=0,"F")))))))) -> A | BC7: =IF(BB7>=91, 4.00, IF(BB7>=81, 3.50, IF(BB7>=70, 3.00, IF(BB7>=65, 2.50, IF(BB7>=60, 2.00, IF(BB7>=55, 1.50, IF(BB7>=50, 1.00, 0.00))))))) | BD7: =IF(BB7>=91,"A",IF(BB7>=81,"B+",IF(BB7>=70,"B",IF(BB7>=65,"C+",IF(BB7>=60,"C",IF(BB7>=55,"D+",IF(BB7>=50,"D","F"))))))) | BE7: =IF(BC7>90,"A",IF(BC7>80,"B+",IF(BC7>69,"B",IF(BC7>64,"C+",IF(BC7>59,"C",IF(BC7>54,"D+",IF(BC7>49,"D",IF(BC7>=0,"F")))))))) -> A | BF7: =IF(BE7>=91, 4.00, IF(BE7>=81, 3.50, IF(BE7>=70, 3.00, IF(BE7>=65, 2.50, IF(BE7>=60, 2.00, IF(BE7>=55, 1.50, IF(BE7>=50, 1.00, 0.00))))))) | BG7: =IF(BE7>=91,"A",IF(BE7>=81,"B+",IF(BE7>=70,"B",IF(BE7>=65,"C+",IF(BE7>=60,"C",IF(BE7>=55,"D+",IF(BE7>=50,"D","F"))))))) | BH7: =IF(BF7>90,"A",IF(BF7>80,"B+",IF(BF7>69,"B",IF(BF7>64,"C+",IF(BF7>59,"C",IF(BF7>54,"D+",IF(BF7>49,"D",IF(BF7>=0,"F")))))))) -> A | BI7: =IF(BH7>=91, 4.00, IF(BH7>=81, 3.50, IF(BH7>=70, 3.00, IF(BH7>=65, 2.50, IF(BH7>=60, 2.00, IF(BH7>=55, 1.50, IF(BH7>=50, 1.00, 0.00))))))) | BJ7: =IF(BH7>=91,"A",IF(BH7>=81,"B+",IF(BH7>=70,"B",IF(BH7>=65,"C+",IF(BH7>=60,"C",IF(BH7>=55,"D+",IF(BH7>=50,"D","F"))))))) | BK7: =IF(BI7>90,"A",IF(BI7>80,"B+",IF(BI7>69,"B",IF(BI7>64,"C+",IF(BI7>59,"C",IF(BI7>54,"D+",IF(BI7>49,"D",IF(BI7>=0,"F")))))))) -> A | BL7: =IF(BK7>=91, 4.00, IF(BK7>=81, 3.50, IF(BK7>=70, 3.00, IF(BK7>=65, 2.50, IF(BK7>=60, 2.00, IF(BK7>=55, 1.50, IF(BK7>=50, 1.00, 0.00))))))) | BM7: =IF(BK7>=91,"A",IF(BK7>=81,"B+",IF(BK7>=70,"B",IF(BK7>=65,"C+",IF(BK7>=60,"C",IF(BK7>=55,"D+",IF(BK7>=50,"D","F"))))))) | BN7: =IF(BL7>90,"A",IF(BL7>80,"B+",IF(BL7>69,"B",IF(BL7>64,"C+",IF(BL7>59,"C",IF(BL7>54,"D+",IF(BL7>49,"D",IF(BL7>=0,"F")))))))) -> A | BO7: =IF(BN7>=91, 4.00, IF(BN7>=81, 3.50, IF(BN7>=70, 3.00, IF(BN7>=65, 2.50, IF(BN7>=60, 2.00, IF(BN7>=55, 1.50, IF(BN7>=50, 1.00, 0.00))))))) | BP7: =IF(BN7>=91,"A",IF(BN7>=81,"B+",IF(BN7>=70,"B",IF(BN7>=65,"C+",IF(BN7>=60,"C",IF(BN7>=55,"D+",IF(BN7>=50,"D","F"))))))) | BQ7: =ROUND((AN7*3+AQ7*2+AT7*1+AW7*2+AZ7*1+BC7*1+BF7*2+BI7*2+BL7*2+BO7*3)/19, 2) | BR7: 87 | BS7: =IF(BR7>90,"4.00",IF(BR7>80,"3.50",IF(BR7>69,"3.00",IF(BR7>64,"2.50",IF(BR7>59,"2.00",IF(BR7>54,"1.50",IF(BR7>49,"1.00","0.00"))))))) -> 3.50 | BT7: =IF(BR7>90,"A",IF(BR7>80,"B+",IF(BR7>69,"B",IF(BR7>64,"C+",IF(BR7>59,"C",IF(BR7>54,"D+",IF(BR7>49,"D",IF(BR7>=0,"F")))))))) -> B+ | BU7: 77 | BV7: =IF(BU7>90,"4.00",IF(BU7>80,"3.50",IF(BU7>69,"3.00",IF(BU7>64,"2.50",IF(BU7>59,"2.00",IF(BU7>54,"1.50",IF(BU7>49,"1.00","0.00"))))))) -> 3.00 | BW7: =IF(BU7>90,"A",IF(BU7>80,"B+",IF(BU7>69,"B",IF(BU7>64,"C+",IF(BU7>59,"C",IF(BU7>54,"D+",IF(BU7>49,"D",IF(BU7>=0,"F")))))))) -> B | BX7: =(AX7*3+BA7*2+BD7*1+BG7*2+BJ7*1+BM7*1+BP7*2+BS7*2+BV7*2)/(3+2+1+2+1+1+2+2+2) -> 3.75 | BY7: =(AL7+BX7)/2 -> 3.5367647 | BZ7: =RANK(BY7,$BY$7:BY32) -> 1
A8: 2 | B8: 125Q0009/23 | C8: ນາງ | D8: ກັນລະຍາ | E8: ໃບຫຼວງລາດ | F8: Ms.Kunlaya | G8: BAILUANELATH | H8: 37683 | I8: ຄຳມ່ວນ | J8: 1 | K8: 50 | L8: =IF(K8>=91, 4.00, IF(K8>=81, 3.50, IF(K8>=70, 3.00, IF(K8>=65, 2.50, IF(K8>=60, 2.00, IF(K8>=55, 1.50, IF(K8>=50, 1.00, 0.00))))))) | M8: =IF(K8>=91,"A",IF(K8>=81,"B+",IF(K8>=70,"B",IF(K8>=65,"C+",IF(K8>=60,"C",IF(K8>=55,"D+",IF(K8>=50,"D","F"))))))) | N8: 79 | O8: =IF(N8>=91, 4.00, IF(N8>=81, 3.50, IF(N8>=70, 3.00, IF(N8>=65, 2.50, IF(N8>=60, 2.00, IF(N8>=55, 1.50, IF(N8>=50, 1.00, 0.00))))))) | P8: =IF(N8>=91,"A",IF(N8>=81,"B+",IF(N8>=70,"B",IF(N8>=65,"C+",IF(N8>=60,"C",IF(N8>=55,"D+",IF(N8>=50,"D","F"))))))) | Q8: 90 | R8: =IF(Q8>=91, 4.00, IF(Q8>=81, 3.50, IF(Q8>=70, 3.00, IF(Q8>=65, 2.50, IF(Q8>=60, 2.00, IF(Q8>=55, 1.50, IF(Q8>=50, 1.00, 0.00))))))) | S8: =IF(Q8>=91,"A",IF(Q8>=81,"B+",IF(Q8>=70,"B",IF(Q8>=65,"C+",IF(Q8>=60,"C",IF(Q8>=55,"D+",IF(Q8>=50,"D","F"))))))) | T8: 56 | U8: =IF(T8>=91, 4.00, IF(T8>=81, 3.50, IF(T8>=70, 3.00, IF(T8>=65, 2.50, IF(T8>=60, 2.00, IF(T8>=55, 1.50, IF(T8>=50, 1.00, 0.00))))))) | V8: =IF(T8>=91,"A",IF(T8>=81,"B+",IF(T8>=70,"B",IF(T8>=65,"C+",IF(T8>=60,"C",IF(T8>=55,"D+",IF(T8>=50,"D","F"))))))) | W8: 35 | X8: =IF(W8>=91, 4.00, IF(W8>=81, 3.50, IF(W8>=70, 3.00, IF(W8>=65, 2.50, IF(W8>=60, 2.00, IF(W8>=55, 1.50, IF(W8>=50, 1.00, 0.00))))))) | Y8: =IF(W8>=91,"A",IF(W8>=81,"B+",IF(W8>=70,"B",IF(W8>=65,"C+",IF(W8>=60,"C",IF(W8>=55,"D+",IF(W8>=50,"D","F"))))))) | Z8: 87.77 | AA8: =IF(Z8>=91, 4.00, IF(Z8>=81, 3.50, IF(Z8>=70, 3.00, IF(Z8>=65, 2.50, IF(Z8>=60, 2.00, IF(Z8>=55, 1.50, IF(Z8>=50, 1.00, 0.00))))))) | AB8: =IF(Z8>=91,"A",IF(Z8>=81,"B+",IF(Z8>=70,"B",IF(Z8>=65,"C+",IF(Z8>=60,"C",IF(Z8>=55,"D+",IF(Z8>=50,"D","F"))))))) | AC8: 75 | AD8: =IF(AC8>=91, 4.00, IF(AC8>=81, 3.50, IF(AC8>=70, 3.00, IF(AC8>=65, 2.50, IF(AC8>=60, 2.00, IF(AC8>=55, 1.50, IF(AC8>=50, 1.00, 0.00))))))) | AE8: =IF(AC8>=91,"A",IF(AC8>=81,"B+",IF(AC8>=70,"B",IF(AC8>=65,"C+",IF(AC8>=60,"C",IF(AC8>=55,"D+",IF(AC8>=50,"D","F"))))))) | AF8: 75 | AG8: =IF(AF8>=91, 4.00, IF(AF8>=81, 3.50, IF(AF8>=70, 3.00, IF(AF8>=65, 2.50, IF(AF8>=60, 2.00, IF(AF8>=55, 1.50, IF(AF8>=50, 1.00, 0.00))))))) | AH8: =IF(AF8>=91,"A",IF(AF8>=81,"B+",IF(AF8>=70,"B",IF(AF8>=65,"C+",IF(AF8>=60,"C",IF(AF8>=55,"D+",IF(AF8>=50,"D","F"))))))) | AI8: 82 | AJ8: =IF(AI8>=91, 4.00, IF(AI8>=81, 3.50, IF(AI8>=70, 3.00, IF(AI8>=65, 2.50, IF(AI8>=60, 2.00, IF(AI8>=55, 1.50, IF(AI8>=50, 1.00, 0.00))))))) | AK8: =IF(AI8>=91,"A",IF(AI8>=81,"B+",IF(AI8>=70,"B",IF(AI8>=65,"C+",IF(AI8>=60,"C",IF(AI8>=55,"D+",IF(AI8>=50,"D","F"))))))) | AL8: =ROUND((L8*3+O8*2+R8*1+U8*2+X8*1+AA8*2+AD8*2+AG8*2+AJ8*2)/17, 2) | AM8: 75 | AN8: =IF(AM8>=91, 4.00, IF(AM8>=81, 3.50, IF(AM8>=70, 3.00, IF(AM8>=65, 2.50, IF(AM8>=60, 2.00, IF(AM8>=55, 1.50, IF(AM8>=50, 1.00, 0.00))))))) | AO8: =IF(AM8>=91,"A",IF(AM8>=81,"B+",IF(AM8>=70,"B",IF(AM8>=65,"C+",IF(AM8>=60,"C",IF(AM8>=55,"D+",IF(AM8>=50,"D","F"))))))) | AP8: ນາງ | AQ8: =IF(AP8>=91, 4.00, IF(AP8>=81, 3.50, IF(AP8>=70, 3.00, IF(AP8>=65, 2.50, IF(AP8>=60, 2.00, IF(AP8>=55, 1.50, IF(AP8>=50, 1.00, 0.00))))))) | AR8: =IF(AP8>=91,"A",IF(AP8>=81,"B+",IF(AP8>=70,"B",IF(AP8>=65,"C+",IF(AP8>=60,"C",IF(AP8>=55,"D+",IF(AP8>=50,"D","F"))))))) | AS8: Ms.Kunlaya | AT8: =IF(AS8>=91, 4.00, IF(AS8>=81, 3.50, IF(AS8>=70, 3.00, IF(AS8>=65, 2.50, IF(AS8>=60, 2.00, IF(AS8>=55, 1.50, IF(AS8>=50, 1.00, 0.00))))))) | AU8: =IF(AS8>=91,"A",IF(AS8>=81,"B+",IF(AS8>=70,"B",IF(AS8>=65,"C+",IF(AS8>=60,"C",IF(AS8>=55,"D+",IF(AS8>=50,"D","F"))))))) | AV8: ຄຳມ່ວນ | AW8: =IF(AV8>=91, 4.00, IF(AV8>=81, 3.50, IF(AV8>=70, 3.00, IF(AV8>=65, 2.50, IF(AV8>=60, 2.00, IF(AV8>=55, 1.50, IF(AV8>=50, 1.00, 0.00))))))) | AX8: =IF(AV8>=91,"A",IF(AV8>=81,"B+",IF(AV8>=70,"B",IF(AV8>=65,"C+",IF(AV8>=60,"C",IF(AV8>=55,"D+",IF(AV8>=50,"D","F"))))))) | AY8: =IF(AW8>90,"A",IF(AW8>80,"B+",IF(AW8>69,"B",IF(AW8>64,"C+",IF(AW8>59,"C",IF(AW8>54,"D+",IF(AW8>49,"D",IF(AW8>=0,"F")))))))) -> C+ | AZ8: =IF(AY8>=91, 4.00, IF(AY8>=81, 3.50, IF(AY8>=70, 3.00, IF(AY8>=65, 2.50, IF(AY8>=60, 2.00, IF(AY8>=55, 1.50, IF(AY8>=50, 1.00, 0.00))))))) | BA8: =IF(AY8>=91,"A",IF(AY8>=81,"B+",IF(AY8>=70,"B",IF(AY8>=65,"C+",IF(AY8>=60,"C",IF(AY8>=55,"D+",IF(AY8>=50,"D","F"))))))) | BB8: =IF(AZ8>90,"A",IF(AZ8>80,"B+",IF(AZ8>69,"B",IF(AZ8>64,"C+",IF(AZ8>59,"C",IF(AZ8>54,"D+",IF(AZ8>49,"D",IF(AZ8>=0,"F")))))))) -> B | BC8: =IF(BB8>=91, 4.00, IF(BB8>=81, 3.50, IF(BB8>=70, 3.00, IF(BB8>=65, 2.50, IF(BB8>=60, 2.00, IF(BB8>=55, 1.50, IF(BB8>=50, 1.00, 0.00))))))) | BD8: =IF(BB8>=91,"A",IF(BB8>=81,"B+",IF(BB8>=70,"B",IF(BB8>=65,"C+",IF(BB8>=60,"C",IF(BB8>=55,"D+",IF(BB8>=50,"D","F"))))))) | BE8: =IF(BC8>90,"A",IF(BC8>80,"B+",IF(BC8>69,"B",IF(BC8>64,"C+",IF(BC8>59,"C",IF(BC8>54,"D+",IF(BC8>49,"D",IF(BC8>=0,"F")))))))) -> B | BF8: =IF(BE8>=91, 4.00, IF(BE8>=81, 3.50, IF(BE8>=70, 3.00, IF(BE8>=65, 2.50, IF(BE8>=60, 2.00, IF(BE8>=55, 1.50, IF(BE8>=50, 1.00, 0.00))))))) | BG8: =IF(BE8>=91,"A",IF(BE8>=81,"B+",IF(BE8>=70,"B",IF(BE8>=65,"C+",IF(BE8>=60,"C",IF(BE8>=55,"D+",IF(BE8>=50,"D","F"))))))) | BH8: =IF(BF8>90,"A",IF(BF8>80,"B+",IF(BF8>69,"B",IF(BF8>64,"C+",IF(BF8>59,"C",IF(BF8>54,"D+",IF(BF8>49,"D",IF(BF8>=0,"F")))))))) -> C+ | BI8: =IF(BH8>=91, 4.00, IF(BH8>=81, 3.50, IF(BH8>=70, 3.00, IF(BH8>=65, 2.50, IF(BH8>=60, 2.00, IF(BH8>=55, 1.50, IF(BH8>=50, 1.00, 0.00))))))) | BJ8: =IF(BH8>=91,"A",IF(BH8>=81,"B+",IF(BH8>=70,"B",IF(BH8>=65,"C+",IF(BH8>=60,"C",IF(BH8>=55,"D+",IF(BH8>=50,"D","F"))))))) | BK8: =IF(BI8>90,"A",IF(BI8>80,"B+",IF(BI8>69,"B",IF(BI8>64,"C+",IF(BI8>59,"C",IF(BI8>54,"D+",IF(BI8>49,"D",IF(BI8>=0,"F")))))))) -> B+ | BL8: =IF(BK8>=91, 4.00, IF(BK8>=81, 3.50, IF(BK8>=70, 3.00, IF(BK8>=65, 2.50, IF(BK8>=60, 2.00, IF(BK8>=55, 1.50, IF(BK8>=50, 1.00, 0.00))))))) | BM8: =IF(BK8>=91,"A",IF(BK8>=81,"B+",IF(BK8>=70,"B",IF(BK8>=65,"C+",IF(BK8>=60,"C",IF(BK8>=55,"D+",IF(BK8>=50,"D","F"))))))) | BN8: =IF(BL8>90,"A",IF(BL8>80,"B+",IF(BL8>69,"B",IF(BL8>64,"C+",IF(BL8>59,"C",IF(BL8>54,"D+",IF(BL8>49,"D",IF(BL8>=0,"F")))))))) -> B | BO8: =IF(BN8>=91, 4.00, IF(BN8>=81, 3.50, IF(BN8>=70, 3.00, IF(BN8>=65, 2.50, IF(BN8>=60, 2.00, IF(BN8>=55, 1.50, IF(BN8>=50, 1.00, 0.00))))))) | BP8: =IF(BN8>=91,"A",IF(BN8>=81,"B+",IF(BN8>=70,"B",IF(BN8>=65,"C+",IF(BN8>=60,"C",IF(BN8>=55,"D+",IF(BN8>=50,"D","F"))))))) | BQ8: =ROUND((AN8*3+AQ8*2+AT8*1+AW8*2+AZ8*1+BC8*1+BF8*2+BI8*2+BL8*2+BO8*3)/19, 2) | BR8: 68 | BS8: =IF(BR8>90,"4.00",IF(BR8>80,"3.50",IF(BR8>69,"3.00",IF(BR8>64,"2.50",IF(BR8>59,"2.00",IF(BR8>54,"1.50",IF(BR8>49,"1.00","0.00"))))))) -> 2.50 | BT8: =IF(BR8>90,"A",IF(BR8>80,"B+",IF(BR8>69,"B",IF(BR8>64,"C+",IF(BR8>59,"C",IF(BR8>54,"D+",IF(BR8>49,"D",IF(BR8>=0,"F")))))))) -> C+ | BU8: 77 | BV8: =IF(BU8>90,"4.00",IF(BU8>80,"3.50",IF(BU8>69,"3.00",IF(BU8>64,"2.50",IF(BU8>59,"2.00",IF(BU8>54,"1.50",IF(BU8>49,"1.00","0.00"))))))) -> 3.00 | BW8: =IF(BU8>90,"A",IF(BU8>80,"B+",IF(BU8>69,"B",IF(BU8>64,"C+",IF(BU8>59,"C",IF(BU8>54,"D+",IF(BU8>49,"D",IF(BU8>=0,"F")))))))) -> B | BX8: =(AX8*3+BA8*2+BD8*1+BG8*2+BJ8*1+BM8*1+BP8*2+BS8*2+BV8*2)/(3+2+1+2+1+1+2+2+2) -> 2.8125 | BY8: =(AL8+BX8)/2 -> 2.5238971 | BZ8: =RANK(BY8,$BY$7:BY38) -> 15
A9: 3 | B9: 125Q0031/23 | C9: ທ້າວ | D9: ມົວຈີລໍ່ | E9: ໄຟຈົງ | F9: Mr.Mouacheelor | G9: FAICHONG | J9: 1 | K9: 0 | L9: =IF(K9>=91, 4.00, IF(K9>=81, 3.50, IF(K9>=70, 3.00, IF(K9>=65, 2.50, IF(K9>=60, 2.00, IF(K9>=55, 1.50, IF(K9>=50, 1.00, 0.00))))))) | M9: =IF(K9>=91,"A",IF(K9>=81,"B+",IF(K9>=70,"B",IF(K9>=65,"C+",IF(K9>=60,"C",IF(K9>=55,"D+",IF(K9>=50,"D","F"))))))) | N9: 27 | O9: =IF(N9>=91, 4.00, IF(N9>=81, 3.50, IF(N9>=70, 3.00, IF(N9>=65, 2.50, IF(N9>=60, 2.00, IF(N9>=55, 1.50, IF(N9>=50, 1.00, 0.00))))))) | P9: =IF(N9>=91,"A",IF(N9>=81,"B+",IF(N9>=70,"B",IF(N9>=65,"C+",IF(N9>=60,"C",IF(N9>=55,"D+",IF(N9>=50,"D","F"))))))) | Q9: 28 | R9: =IF(Q9>=91, 4.00, IF(Q9>=81, 3.50, IF(Q9>=70, 3.00, IF(Q9>=65, 2.50, IF(Q9>=60, 2.00, IF(Q9>=55, 1.50, IF(Q9>=50, 1.00, 0.00))))))) | S9: =IF(Q9>=91,"A",IF(Q9>=81,"B+",IF(Q9>=70,"B",IF(Q9>=65,"C+",IF(Q9>=60,"C",IF(Q9>=55,"D+",IF(Q9>=50,"D","F"))))))) | T9: 0 | U9: =IF(T9>=91, 4.00, IF(T9>=81, 3.50, IF(T9>=70, 3.00, IF(T9>=65, 2.50, IF(T9>=60, 2.00, IF(T9>=55, 1.50, IF(T9>=50, 1.00, 0.00))))))) | V9: =IF(T9>=91,"A",IF(T9>=81,"B+",IF(T9>=70,"B",IF(T9>=65,"C+",IF(T9>=60,"C",IF(T9>=55,"D+",IF(T9>=50,"D","F"))))))) | W9: 0 | X9: =IF(W9>=91, 4.00, IF(W9>=81, 3.50, IF(W9>=70, 3.00, IF(W9>=65, 2.50, IF(W9>=60, 2.00, IF(W9>=55, 1.50, IF(W9>=50, 1.00, 0.00))))))) | Y9: =IF(W9>=91,"A",IF(W9>=81,"B+",IF(W9>=70,"B",IF(W9>=65,"C+",IF(W9>=60,"C",IF(W9>=55,"D+",IF(W9>=50,"D","F"))))))) | Z9: 12.29 | AA9: =IF(Z9>=91, 4.00, IF(Z9>=81, 3.50, IF(Z9>=70, 3.00, IF(Z9>=65, 2.50, IF(Z9>=60, 2.00, IF(Z9>=55, 1.50, IF(Z9>=50, 1.00, 0.00))))))) | AB9: =IF(Z9>=91,"A",IF(Z9>=81,"B+",IF(Z9>=70,"B",IF(Z9>=65,"C+",IF(Z9>=60,"C",IF(Z9>=55,"D+",IF(Z9>=50,"D","F"))))))) | AC9: 28 | AD9: =IF(AC9>=91, 4.00, IF(AC9>=81, 3.50, IF(AC9>=70, 3.00, IF(AC9>=65, 2.50, IF(AC9>=60, 2.00, IF(AC9>=55, 1.50, IF(AC9>=50, 1.00, 0.00))))))) | AE9: =IF(AC9>=91,"A",IF(AC9>=81,"B+",IF(AC9>=70,"B",IF(AC9>=65,"C+",IF(AC9>=60,"C",IF(AC9>=55,"D+",IF(AC9>=50,"D","F"))))))) | AF9: 27 | AG9: =IF(AF9>=91, 4.00, IF(AF9>=81, 3.50, IF(AF9>=70, 3.00, IF(AF9>=65, 2.50, IF(AF9>=60, 2.00, IF(AF9>=55, 1.50, IF(AF9>=50, 1.00, 0.00))))))) | AH9: =IF(AF9>=91,"A",IF(AF9>=81,"B+",IF(AF9>=70,"B",IF(AF9>=65,"C+",IF(AF9>=60,"C",IF(AF9>=55,"D+",IF(AF9>=50,"D","F"))))))) | AI9: 83 | AJ9: =IF(AI9>=91, 4.00, IF(AI9>=81, 3.50, IF(AI9>=70, 3.00, IF(AI9>=65, 2.50, IF(AI9>=60, 2.00, IF(AI9>=55, 1.50, IF(AI9>=50, 1.00, 0.00))))))) | AK9: =IF(AI9>=91,"A",IF(AI9>=81,"B+",IF(AI9>=70,"B",IF(AI9>=65,"C+",IF(AI9>=60,"C",IF(AI9>=55,"D+",IF(AI9>=50,"D","F"))))))) | AL9: =ROUND((L9*3+O9*2+R9*1+U9*2+X9*1+AA9*2+AD9*2+AG9*2+AJ9*2)/17, 2) | AM9: 78 | AN9: =IF(AM9>=91, 4.00, IF(AM9>=81, 3.50, IF(AM9>=70, 3.00, IF(AM9>=65, 2.50, IF(AM9>=60, 2.00, IF(AM9>=55, 1.50, IF(AM9>=50, 1.00, 0.00))))))) | AO9: =IF(AM9>=91,"A",IF(AM9>=81,"B+",IF(AM9>=70,"B",IF(AM9>=65,"C+",IF(AM9>=60,"C",IF(AM9>=55,"D+",IF(AM9>=50,"D","F"))))))) | AP9: ທ້າວ | AQ9: =IF(AP9>=91, 4.00, IF(AP9>=81, 3.50, IF(AP9>=70, 3.00, IF(AP9>=65, 2.50, IF(AP9>=60, 2.00, IF(AP9>=55, 1.50, IF(AP9>=50, 1.00, 0.00))))))) | AR9: =IF(AP9>=91,"A",IF(AP9>=81,"B+",IF(AP9>=70,"B",IF(AP9>=65,"C+",IF(AP9>=60,"C",IF(AP9>=55,"D+",IF(AP9>=50,"D","F"))))))) | AS9: Mr.Mouacheelor | AT9: =IF(AS9>=91, 4.00, IF(AS9>=81, 3.50, IF(AS9>=70, 3.00, IF(AS9>=65, 2.50, IF(AS9>=60, 2.00, IF(AS9>=55, 1.50, IF(AS9>=50, 1.00, 0.00))))))) | AU9: =IF(AS9>=91,"A",IF(AS9>=81,"B+",IF(AS9>=70,"B",IF(AS9>=65,"C+",IF(AS9>=60,"C",IF(AS9>=55,"D+",IF(AS9>=50,"D","F"))))))) | AV9: 87 | AW9: =IF(AV9>=91, 4.00, IF(AV9>=81, 3.50, IF(AV9>=70, 3.00, IF(AV9>=65, 2.50, IF(AV9>=60, 2.00, IF(AV9>=55, 1.50, IF(AV9>=50, 1.00, 0.00))))))) | AX9: =IF(AV9>=91,"A",IF(AV9>=81,"B+",IF(AV9>=70,"B",IF(AV9>=65,"C+",IF(AV9>=60,"C",IF(AV9>=55,"D+",IF(AV9>=50,"D","F"))))))) | AY9: =IF(AW9>90,"A",IF(AW9>80,"B+",IF(AW9>69,"B",IF(AW9>64,"C+",IF(AW9>59,"C",IF(AW9>54,"D+",IF(AW9>49,"D",IF(AW9>=0,"F")))))))) -> F | AZ9: =IF(AY9>=91, 4.00, IF(AY9>=81, 3.50, IF(AY9>=70, 3.00, IF(AY9>=65, 2.50, IF(AY9>=60, 2.00, IF(AY9>=55, 1.50, IF(AY9>=50, 1.00, 0.00))))))) | BA9: =IF(AY9>=91,"A",IF(AY9>=81,"B+",IF(AY9>=70,"B",IF(AY9>=65,"C+",IF(AY9>=60,"C",IF(AY9>=55,"D+",IF(AY9>=50,"D","F"))))))) | BB9: =IF(AZ9>90,"A",IF(AZ9>80,"B+",IF(AZ9>69,"B",IF(AZ9>64,"C+",IF(AZ9>59,"C",IF(AZ9>54,"D+",IF(AZ9>49,"D",IF(AZ9>=0,"F")))))))) -> F | BC9: =IF(BB9>=91, 4.00, IF(BB9>=81, 3.50, IF(BB9>=70, 3.00, IF(BB9>=65, 2.50, IF(BB9>=60, 2.00, IF(BB9>=55, 1.50, IF(BB9>=50, 1.00, 0.00))))))) | BD9: =IF(BB9>=91,"A",IF(BB9>=81,"B+",IF(BB9>=70,"B",IF(BB9>=65,"C+",IF(BB9>=60,"C",IF(BB9>=55,"D+",IF(BB9>=50,"D","F"))))))) | BE9: =IF(BC9>90,"A",IF(BC9>80,"B+",IF(BC9>69,"B",IF(BC9>64,"C+",IF(BC9>59,"C",IF(BC9>54,"D+",IF(BC9>49,"D",IF(BC9>=0,"F")))))))) -> F | BF9: =IF(BE9>=91, 4.00, IF(BE9>=81, 3.50, IF(BE9>=70, 3.00, IF(BE9>=65, 2.50, IF(BE9>=60, 2.00, IF(BE9>=55, 1.50, IF(BE9>=50, 1.00, 0.00))))))) | BG9: =IF(BE9>=91,"A",IF(BE9>=81,"B+",IF(BE9>=70,"B",IF(BE9>=65,"C+",IF(BE9>=60,"C",IF(BE9>=55,"D+",IF(BE9>=50,"D","F"))))))) | BH9: =IF(BF9>90,"A",IF(BF9>80,"B+",IF(BF9>69,"B",IF(BF9>64,"C+",IF(BF9>59,"C",IF(BF9>54,"D+",IF(BF9>49,"D",IF(BF9>=0,"F")))))))) -> F | BI9: =IF(BH9>=91, 4.00, IF(BH9>=81, 3.50, IF(BH9>=70, 3.00, IF(BH9>=65, 2.50, IF(BH9>=60, 2.00, IF(BH9>=55, 1.50, IF(BH9>=50, 1.00, 0.00))))))) | BJ9: =IF(BH9>=91,"A",IF(BH9>=81,"B+",IF(BH9>=70,"B",IF(BH9>=65,"C+",IF(BH9>=60,"C",IF(BH9>=55,"D+",IF(BH9>=50,"D","F"))))))) | BK9: =IF(BI9>90,"A",IF(BI9>80,"B+",IF(BI9>69,"B",IF(BI9>64,"C+",IF(BI9>59,"C",IF(BI9>54,"D+",IF(BI9>49,"D",IF(BI9>=0,"F")))))))) -> F | BL9: =IF(BK9>=91, 4.00, IF(BK9>=81, 3.50, IF(BK9>=70, 3.00, IF(BK9>=65, 2.50, IF(BK9>=60, 2.00, IF(BK9>=55, 1.50, IF(BK9>=50, 1.00, 0.00))))))) | BM9: =IF(BK9>=91,"A",IF(BK9>=81,"B+",IF(BK9>=70,"B",IF(BK9>=65,"C+",IF(BK9>=60,"C",IF(BK9>=55,"D+",IF(BK9>=50,"D","F"))))))) | BN9: =IF(BL9>90,"A",IF(BL9>80,"B+",IF(BL9>69,"B",IF(BL9>64,"C+",IF(BL9>59,"C",IF(BL9>54,"D+",IF(BL9>49,"D",IF(BL9>=0,"F")))))))) -> F | BO9: =IF(BN9>=91, 4.00, IF(BN9>=81, 3.50, IF(BN9>=70, 3.00, IF(BN9>=65, 2.50, IF(BN9>=60, 2.00, IF(BN9>=55, 1.50, IF(BN9>=50, 1.00, 0.00))))))) | BP9: =IF(BN9>=91,"A",IF(BN9>=81,"B+",IF(BN9>=70,"B",IF(BN9>=65,"C+",IF(BN9>=60,"C",IF(BN9>=55,"D+",IF(BN9>=50,"D","F"))))))) | BQ9: =ROUND((AN9*3+AQ9*2+AT9*1+AW9*2+AZ9*1+BC9*1+BF9*2+BI9*2+BL9*2+BO9*3)/19, 2) | BS9: =IF(BR9>90,"4.00",IF(BR9>80,"3.50",IF(BR9>69,"3.00",IF(BR9>64,"2.50",IF(BR9>59,"2.00",IF(BR9>54,"1.50",IF(BR9>49,"1.00","0.00"))))))) -> 0.00 | BT9: =IF(BR9>90,"A",IF(BR9>80,"B+",IF(BR9>69,"B",IF(BR9>64,"C+",IF(BR9>59,"C",IF(BR9>54,"D+",IF(BR9>49,"D",IF(BR9>=0,"F")))))))) -> F | BV9: =IF(BU9>90,"4.00",IF(BU9>80,"3.50",IF(BU9>69,"3.00",IF(BU9>64,"2.50",IF(BU9>59,"2.00",IF(BU9>54,"1.50",IF(BU9>49,"1.00","0.00"))))))) -> 0.00 | BW9: =IF(BU9>90,"A",IF(BU9>80,"B+",IF(BU9>69,"B",IF(BU9>64,"C+",IF(BU9>59,"C",IF(BU9>54,"D+",IF(BU9>49,"D",IF(BU9>=0,"F")))))))) -> F | BX9: =(AX9*3+BA9*2+BD9*1+BG9*2+BJ9*1+BM9*1+BP9*2+BS9*2+BV9*2)/(3+2+1+2+1+1+2+2+2) -> 0 | BY9: =(AL9+BX9)/2 -> 0.20588235 | BZ9: =RANK(BY9,$BY$7:BY39) -> 30
A10: 4 | B10: 125Q0041/23 | C10: ນາງ | D10: ເຊຍນາຢ່າງ | E10: ຊາວາ | F10: Ms.Xianayang | G10: ZAVA | H10: 21/12/2006 | I10: ໄຊສົມບູນ | J10: 1 | K10: 37 | L10: =IF(K10>=91, 4.00, IF(K10>=81, 3.50, IF(K10>=70, 3.00, IF(K10>=65, 2.50, IF(K10>=60, 2.00, IF(K10>=55, 1.50, IF(K10>=50, 1.00, 0.00))))))) | M10: =IF(K10>=91,"A",IF(K10>=81,"B+",IF(K10>=70,"B",IF(K10>=65,"C+",IF(K10>=60,"C",IF(K10>=55,"D+",IF(K10>=50,"D","F"))))))) | N10: 57 | O10: =IF(N10>=91, 4.00, IF(N10>=81, 3.50, IF(N10>=70, 3.00, IF(N10>=65, 2.50, IF(N10>=60, 2.00, IF(N10>=55, 1.50, IF(N10>=50, 1.00, 0.00))))))) | P10: =IF(N10>=91,"A",IF(N10>=81,"B+",IF(N10>=70,"B",IF(N10>=65,"C+",IF(N10>=60,"C",IF(N10>=55,"D+",IF(N10>=50,"D","F"))))))) | Q10: 87 | R10: =IF(Q10>=91, 4.00, IF(Q10>=81, 3.50, IF(Q10>=70, 3.00, IF(Q10>=65, 2.50, IF(Q10>=60, 2.00, IF(Q10>=55, 1.50, IF(Q10>=50, 1.00, 0.00))))))) | S10: =IF(Q10>=91,"A",IF(Q10>=81,"B+",IF(Q10>=70,"B",IF(Q10>=65,"C+",IF(Q10>=60,"C",IF(Q10>=55,"D+",IF(Q10>=50,"D","F"))))))) | T10: 48 | U10: =IF(T10>=91, 4.00, IF(T10>=81, 3.50, IF(T10>=70, 3.00, IF(T10>=65, 2.50, IF(T10>=60, 2.00, IF(T10>=55, 1.50, IF(T10>=50, 1.00, 0.00))))))) | V10: =IF(T10>=91,"A",IF(T10>=81,"B+",IF(T10>=70,"B",IF(T10>=65,"C+",IF(T10>=60,"C",IF(T10>=55,"D+",IF(T10>=50,"D","F"))))))) | W10: 29 | X10: =IF(W10>=91, 4.00, IF(W10>=81, 3.50, IF(W10>=70, 3.00, IF(W10>=65, 2.50, IF(W10>=60, 2.00, IF(W10>=55, 1.50, IF(W10>=50, 1.00, 0.00))))))) | Y10: =IF(W10>=91,"A",IF(W10>=81,"B+",IF(W10>=70,"B",IF(W10>=65,"C+",IF(W10>=60,"C",IF(W10>=55,"D+",IF(W10>=50,"D","F"))))))) | Z10: 82.64 | AA10: =IF(Z10>=91, 4.00, IF(Z10>=81, 3.50, IF(Z10>=70, 3.00, IF(Z10>=65, 2.50, IF(Z10>=60, 2.00, IF(Z10>=55, 1.50, IF(Z10>=50, 1.00, 0.00))))))) | AB10: =IF(Z10>=91,"A",IF(Z10>=81,"B+",IF(Z10>=70,"B",IF(Z10>=65,"C+",IF(Z10>=60,"C",IF(Z10>=55,"D+",IF(Z10>=50,"D","F"))))))) | AC10: 58.25 | AD10: =IF(AC10>=91, 4.00, IF(AC10>=81, 3.50, IF(AC10>=70, 3.00, IF(AC10>=65, 2.50, IF(AC10>=60, 2.00, IF(AC10>=55, 1.50, IF(AC10>=50, 1.00, 0.00))))))) | AE10: =IF(AC10>=91,"A",IF(AC10>=81,"B+",IF(AC10>=70,"B",IF(AC10>=65,"C+",IF(AC10>=60,"C",IF(AC10>=55,"D+",IF(AC10>=50,"D","F"))))))) | AF10: 70 | AG10: =IF(AF10>=91, 4.00, IF(AF10>=81, 3.50, IF(AF10>=70, 3.00, IF(AF10>=65, 2.50, IF(AF10>=60, 2.00, IF(AF10>=55, 1.50, IF(AF10>=50, 1.00, 0.00))))))) | AH10: =IF(AF10>=91,"A",IF(AF10>=81,"B+",IF(AF10>=70,"B",IF(AF10>=65,"C+",IF(AF10>=60,"C",IF(AF10>=55,"D+",IF(AF10>=50,"D","F"))))))) | AI10: 84 | AJ10: =IF(AI10>=91, 4.00, IF(AI10>=81, 3.50, IF(AI10>=70, 3.00, IF(AI10>=65, 2.50, IF(AI10>=60, 2.00, IF(AI10>=55, 1.50, IF(AI10>=50, 1.00, 0.00))))))) | AK10: =IF(AI10>=91,"A",IF(AI10>=81,"B+",IF(AI10>=70,"B",IF(AI10>=65,"C+",IF(AI10>=60,"C",IF(AI10>=55,"D+",IF(AI10>=50,"D","F"))))))) | AL10: =ROUND((L10*3+O10*2+R10*1+U10*2+X10*1+AA10*2+AD10*2+AG10*2+AJ10*2)/17, 2) | AM10: 81 | AN10: =IF(AM10>=91, 4.00, IF(AM10>=81, 3.50, IF(AM10>=70, 3.00, IF(AM10>=65, 2.50, IF(AM10>=60, 2.00, IF(AM10>=55, 1.50, IF(AM10>=50, 1.00, 0.00))))))) | AO10: =IF(AM10>=91,"A",IF(AM10>=81,"B+",IF(AM10>=70,"B",IF(AM10>=65,"C+",IF(AM10>=60,"C",IF(AM10>=55,"D+",IF(AM10>=50,"D","F"))))))) | AP10: ນາງ | AQ10: =IF(AP10>=91, 4.00, IF(AP10>=81, 3.50, IF(AP10>=70, 3.00, IF(AP10>=65, 2.50, IF(AP10>=60, 2.00, IF(AP10>=55, 1.50, IF(AP10>=50, 1.00, 0.00))))))) | AR10: =IF(AP10>=91,"A",IF(AP10>=81,"B+",IF(AP10>=70,"B",IF(AP10>=65,"C+",IF(AP10>=60,"C",IF(AP10>=55,"D+",IF(AP10>=50,"D","F"))))))) | AS10: Ms.Xianayang | AT10: =IF(AS10>=91, 4.00, IF(AS10>=81, 3.50, IF(AS10>=70, 3.00, IF(AS10>=65, 2.50, IF(AS10>=60, 2.00, IF(AS10>=55, 1.50, IF(AS10>=50, 1.00, 0.00))))))) | AU10: =IF(AS10>=91,"A",IF(AS10>=81,"B+",IF(AS10>=70,"B",IF(AS10>=65,"C+",IF(AS10>=60,"C",IF(AS10>=55,"D+",IF(AS10>=50,"D","F"))))))) | AV10: ໄຊສົມບູນ | AW10: =IF(AV10>=91, 4.00, IF(AV10>=81, 3.50, IF(AV10>=70, 3.00, IF(AV10>=65, 2.50, IF(AV10>=60, 2.00, IF(AV10>=55, 1.50, IF(AV10>=50, 1.00, 0.00))))))) | AX10: =IF(AV10>=91,"A",IF(AV10>=81,"B+",IF(AV10>=70,"B",IF(AV10>=65,"C+",IF(AV10>=60,"C",IF(AV10>=55,"D+",IF(AV10>=50,"D","F"))))))) | AY10: =IF(AW10>90,"A",IF(AW10>80,"B+",IF(AW10>69,"B",IF(AW10>64,"C+",IF(AW10>59,"C",IF(AW10>54,"D+",IF(AW10>49,"D",IF(AW10>=0,"F")))))))) -> B | AZ10: =IF(AY10>=91, 4.00, IF(AY10>=81, 3.50, IF(AY10>=70, 3.00, IF(AY10>=65, 2.50, IF(AY10>=60, 2.00, IF(AY10>=55, 1.50, IF(AY10>=50, 1.00, 0.00))))))) | BA10: =IF(AY10>=91,"A",IF(AY10>=81,"B+",IF(AY10>=70,"B",IF(AY10>=65,"C+",IF(AY10>=60,"C",IF(AY10>=55,"D+",IF(AY10>=50,"D","F"))))))) | BB10: =IF(AZ10>90,"A",IF(AZ10>80,"B+",IF(AZ10>69,"B",IF(AZ10>64,"C+",IF(AZ10>59,"C",IF(AZ10>54,"D+",IF(AZ10>49,"D",IF(AZ10>=0,"F")))))))) -> C | BC10: =IF(BB10>=91, 4.00, IF(BB10>=81, 3.50, IF(BB10>=70, 3.00, IF(BB10>=65, 2.50, IF(BB10>=60, 2.00, IF(BB10>=55, 1.50, IF(BB10>=50, 1.00, 0.00))))))) | BD10: =IF(BB10>=91,"A",IF(BB10>=81,"B+",IF(BB10>=70,"B",IF(BB10>=65,"C+",IF(BB10>=60,"C",IF(BB10>=55,"D+",IF(BB10>=50,"D","F"))))))) | BE10: =IF(BC10>90,"A",IF(BC10>80,"B+",IF(BC10>69,"B",IF(BC10>64,"C+",IF(BC10>59,"C",IF(BC10>54,"D+",IF(BC10>49,"D",IF(BC10>=0,"F")))))))) -> D+ | BF10: =IF(BE10>=91, 4.00, IF(BE10>=81, 3.50, IF(BE10>=70, 3.00, IF(BE10>=65, 2.50, IF(BE10>=60, 2.00, IF(BE10>=55, 1.50, IF(BE10>=50, 1.00, 0.00))))))) | BG10: =IF(BE10>=91,"A",IF(BE10>=81,"B+",IF(BE10>=70,"B",IF(BE10>=65,"C+",IF(BE10>=60,"C",IF(BE10>=55,"D+",IF(BE10>=50,"D","F"))))))) | BH10: =IF(BF10>90,"A",IF(BF10>80,"B+",IF(BF10>69,"B",IF(BF10>64,"C+",IF(BF10>59,"C",IF(BF10>54,"D+",IF(BF10>49,"D",IF(BF10>=0,"F")))))))) -> D | BI10: =IF(BH10>=91, 4.00, IF(BH10>=81, 3.50, IF(BH10>=70, 3.00, IF(BH10>=65, 2.50, IF(BH10>=60, 2.00, IF(BH10>=55, 1.50, IF(BH10>=50, 1.00, 0.00))))))) | BJ10: =IF(BH10>=91,"A",IF(BH10>=81,"B+",IF(BH10>=70,"B",IF(BH10>=65,"C+",IF(BH10>=60,"C",IF(BH10>=55,"D+",IF(BH10>=50,"D","F"))))))) | BK10: =IF(BI10>90,"A",IF(BI10>80,"B+",IF(BI10>69,"B",IF(BI10>64,"C+",IF(BI10>59,"C",IF(BI10>54,"D+",IF(BI10>49,"D",IF(BI10>=0,"F")))))))) -> B | BL10: =IF(BK10>=91, 4.00, IF(BK10>=81, 3.50, IF(BK10>=70, 3.00, IF(BK10>=65, 2.50, IF(BK10>=60, 2.00, IF(BK10>=55, 1.50, IF(BK10>=50, 1.00, 0.00))))))) | BM10: =IF(BK10>=91,"A",IF(BK10>=81,"B+",IF(BK10>=70,"B",IF(BK10>=65,"C+",IF(BK10>=60,"C",IF(BK10>=55,"D+",IF(BK10>=50,"D","F"))))))) | BN10: =IF(BL10>90,"A",IF(BL10>80,"B+",IF(BL10>69,"B",IF(BL10>64,"C+",IF(BL10>59,"C",IF(BL10>54,"D+",IF(BL10>49,"D",IF(BL10>=0,"F")))))))) -> C | BO10: =IF(BN10>=91, 4.00, IF(BN10>=81, 3.50, IF(BN10>=70, 3.00, IF(BN10>=65, 2.50, IF(BN10>=60, 2.00, IF(BN10>=55, 1.50, IF(BN10>=50, 1.00, 0.00))))))) | BP10: =IF(BN10>=91,"A",IF(BN10>=81,"B+",IF(BN10>=70,"B",IF(BN10>=65,"C+",IF(BN10>=60,"C",IF(BN10>=55,"D+",IF(BN10>=50,"D","F"))))))) | BQ10: =ROUND((AN10*3+AQ10*2+AT10*1+AW10*2+AZ10*1+BC10*1+BF10*2+BI10*2+BL10*2+BO10*3)/19, 2) | BR10: 52 | BS10: =IF(BR10>90,"4.00",IF(BR10>80,"3.50",IF(BR10>69,"3.00",IF(BR10>64,"2.50",IF(BR10>59,"2.00",IF(BR10>54,"1.50",IF(BR10>49,"1.00","0.00"))))))) -> 1.00 | BT10: =IF(BR10>90,"A",IF(BR10>80,"B+",IF(BR10>69,"B",IF(BR10>64,"C+",IF(BR10>59,"C",IF(BR10>54,"D+",IF(BR10>49,"D",IF(BR10>=0,"F")))))))) -> D | BU10: 62 | BV10: =IF(BU10>90,"4.00",IF(BU10>80,"3.50",IF(BU10>69,"3.00",IF(BU10>64,"2.50",IF(BU10>59,"2.00",IF(BU10>54,"1.50",IF(BU10>49,"1.00","0.00"))))))) -> 2.00 | BW10: =IF(BU10>90,"A",IF(BU10>80,"B+",IF(BU10>69,"B",IF(BU10>64,"C+",IF(BU10>59,"C",IF(BU10>54,"D+",IF(BU10>49,"D",IF(BU10>=0,"F")))))))) -> C | BX10: =(AX10*3+BA10*2+BD10*1+BG10*2+BJ10*1+BM10*1+BP10*2+BS10*2+BV10*2)/(3+2+1+2+1+1+2+2+2) -> 2.03125 | BY10: =(AL10+BX10)/2 -> 1.7803309 | BZ10: =RANK(BY10,$BY$7:BY37) -> 19
A11: 5 | B11: 125Q0047/23 | C11: ນາງ | D11: ວິໄລພອນ | E11: ຈັນທະແສງ | F11: Ms.Vilaiphone | G11: CHANTHASENG | H11: 38691 | I11: ນະຄອນຫຼວງວຽງຈັນ | J11: 1 | K11: 26 | L11: =IF(K11>=91, 4.00, IF(K11>=81, 3.50, IF(K11>=70, 3.00, IF(K11>=65, 2.50, IF(K11>=60, 2.00, IF(K11>=55, 1.50, IF(K11>=50, 1.00, 0.00))))))) | M11: =IF(K11>=91,"A",IF(K11>=81,"B+",IF(K11>=70,"B",IF(K11>=65,"C+",IF(K11>=60,"C",IF(K11>=55,"D+",IF(K11>=50,"D","F"))))))) | N11: 52 | O11: =IF(N11>=91, 4.00, IF(N11>=81, 3.50, IF(N11>=70, 3.00, IF(N11>=65, 2.50, IF(N11>=60, 2.00, IF(N11>=55, 1.50, IF(N11>=50, 1.00, 0.00))))))) | P11: =IF(N11>=91,"A",IF(N11>=81,"B+",IF(N11>=70,"B",IF(N11>=65,"C+",IF(N11>=60,"C",IF(N11>=55,"D+",IF(N11>=50,"D","F"))))))) | Q11: 57 | R11: =IF(Q11>=91, 4.00, IF(Q11>=81, 3.50, IF(Q11>=70, 3.00, IF(Q11>=65, 2.50, IF(Q11>=60, 2.00, IF(Q11>=55, 1.50, IF(Q11>=50, 1.00, 0.00))))))) | S11: =IF(Q11>=91,"A",IF(Q11>=81,"B+",IF(Q11>=70,"B",IF(Q11>=65,"C+",IF(Q11>=60,"C",IF(Q11>=55,"D+",IF(Q11>=50,"D","F"))))))) | T11: 46 | U11: =IF(T11>=91, 4.00, IF(T11>=81, 3.50, IF(T11>=70, 3.00, IF(T11>=65, 2.50, IF(T11>=60, 2.00, IF(T11>=55, 1.50, IF(T11>=50, 1.00, 0.00))))))) | V11: =IF(T11>=91,"A",IF(T11>=81,"B+",IF(T11>=70,"B",IF(T11>=65,"C+",IF(T11>=60,"C",IF(T11>=55,"D+",IF(T11>=50,"D","F"))))))) | W11: 28 | X11: =IF(W11>=91, 4.00, IF(W11>=81, 3.50, IF(W11>=70, 3.00, IF(W11>=65, 2.50, IF(W11>=60, 2.00, IF(W11>=55, 1.50, IF(W11>=50, 1.00, 0.00))))))) | Y11: =IF(W11>=91,"A",IF(W11>=81,"B+",IF(W11>=70,"B",IF(W11>=65,"C+",IF(W11>=60,"C",IF(W11>=55,"D+",IF(W11>=50,"D","F"))))))) | Z11: 87.29 | AA11: =IF(Z11>=91, 4.00, IF(Z11>=81, 3.50, IF(Z11>=70, 3.00, IF(Z11>=65, 2.50, IF(Z11>=60, 2.00, IF(Z11>=55, 1.50, IF(Z11>=50, 1.00, 0.00))))))) | AB11: =IF(Z11>=91,"A",IF(Z11>=81,"B+",IF(Z11>=70,"B",IF(Z11>=65,"C+",IF(Z11>=60,"C",IF(Z11>=55,"D+",IF(Z11>=50,"D","F"))))))) | AC11: 58 | AD11: =IF(AC11>=91, 4.00, IF(AC11>=81, 3.50, IF(AC11>=70, 3.00, IF(AC11>=65, 2.50, IF(AC11>=60, 2.00, IF(AC11>=55, 1.50, IF(AC11>=50, 1.00, 0.00))))))) | AE11: =IF(AC11>=91,"A",IF(AC11>=81,"B+",IF(AC11>=70,"B",IF(AC11>=65,"C+",IF(AC11>=60,"C",IF(AC11>=55,"D+",IF(AC11>=50,"D","F"))))))) | AF11: 76 | AG11: =IF(AF11>=91, 4.00, IF(AF11>=81, 3.50, IF(AF11>=70, 3.00, IF(AF11>=65, 2.50, IF(AF11>=60, 2.00, IF(AF11>=55, 1.50, IF(AF11>=50, 1.00, 0.00))))))) | AH11: =IF(AF11>=91,"A",IF(AF11>=81,"B+",IF(AF11>=70,"B",IF(AF11>=65,"C+",IF(AF11>=60,"C",IF(AF11>=55,"D+",IF(AF11>=50,"D","F"))))))) | AI11: 85 | AJ11: =IF(AI11>=91, 4.00, IF(AI11>=81, 3.50, IF(AI11>=70, 3.00, IF(AI11>=65, 2.50, IF(AI11>=60, 2.00, IF(AI11>=55, 1.50, IF(AI11>=50, 1.00, 0.00))))))) | AK11: =IF(AI11>=91,"A",IF(AI11>=81,"B+",IF(AI11>=70,"B",IF(AI11>=65,"C+",IF(AI11>=60,"C",IF(AI11>=55,"D+",IF(AI11>=50,"D","F"))))))) | AL11: =ROUND((L11*3+O11*2+R11*1+U11*2+X11*1+AA11*2+AD11*2+AG11*2+AJ11*2)/17, 2) | AM11: 84 | AN11: =IF(AM11>=91, 4.00, IF(AM11>=81, 3.50, IF(AM11>=70, 3.00, IF(AM11>=65, 2.50, IF(AM11>=60, 2.00, IF(AM11>=55, 1.50, IF(AM11>=50, 1.00, 0.00))))))) | AO11: =IF(AM11>=91,"A",IF(AM11>=81,"B+",IF(AM11>=70,"B",IF(AM11>=65,"C+",IF(AM11>=60,"C",IF(AM11>=55,"D+",IF(AM11>=50,"D","F"))))))) | AP11: ນາງ | AQ11: =IF(AP11>=91, 4.00, IF(AP11>=81, 3.50, IF(AP11>=70, 3.00, IF(AP11>=65, 2.50, IF(AP11>=60, 2.00, IF(AP11>=55, 1.50, IF(AP11>=50, 1.00, 0.00))))))) | AR11: =IF(AP11>=91,"A",IF(AP11>=81,"B+",IF(AP11>=70,"B",IF(AP11>=65,"C+",IF(AP11>=60,"C",IF(AP11>=55,"D+",IF(AP11>=50,"D","F"))))))) | AS11: Ms.Vilaiphone | AT11: =IF(AS11>=91, 4.00, IF(AS11>=81, 3.50, IF(AS11>=70, 3.00, IF(AS11>=65, 2.50, IF(AS11>=60, 2.00, IF(AS11>=55, 1.50, IF(AS11>=50, 1.00, 0.00))))))) | AU11: =IF(AS11>=91,"A",IF(AS11>=81,"B+",IF(AS11>=70,"B",IF(AS11>=65,"C+",IF(AS11>=60,"C",IF(AS11>=55,"D+",IF(AS11>=50,"D","F"))))))) | AV11: ນະຄອນຫຼວງວຽງຈັນ | AW11: =IF(AV11>=91, 4.00, IF(AV11>=81, 3.50, IF(AV11>=70, 3.00, IF(AV11>=65, 2.50, IF(AV11>=60, 2.00, IF(AV11>=55, 1.50, IF(AV11>=50, 1.00, 0.00))))))) | AX11: =IF(AV11>=91,"A",IF(AV11>=81,"B+",IF(AV11>=70,"B",IF(AV11>=65,"C+",IF(AV11>=60,"C",IF(AV11>=55,"D+",IF(AV11>=50,"D","F"))))))) | AY11: =IF(AW11>90,"A",IF(AW11>80,"B+",IF(AW11>69,"B",IF(AW11>64,"C+",IF(AW11>59,"C",IF(AW11>54,"D+",IF(AW11>49,"D",IF(AW11>=0,"F")))))))) -> F | AZ11: =IF(AY11>=91, 4.00, IF(AY11>=81, 3.50, IF(AY11>=70, 3.00, IF(AY11>=65, 2.50, IF(AY11>=60, 2.00, IF(AY11>=55, 1.50, IF(AY11>=50, 1.00, 0.00))))))) | BA11: =IF(AY11>=91,"A",IF(AY11>=81,"B+",IF(AY11>=70,"B",IF(AY11>=65,"C+",IF(AY11>=60,"C",IF(AY11>=55,"D+",IF(AY11>=50,"D","F"))))))) | BB11: =IF(AZ11>90,"A",IF(AZ11>80,"B+",IF(AZ11>69,"B",IF(AZ11>64,"C+",IF(AZ11>59,"C",IF(AZ11>54,"D+",IF(AZ11>49,"D",IF(AZ11>=0,"F")))))))) -> F | BC11: =IF(BB11>=91, 4.00, IF(BB11>=81, 3.50, IF(BB11>=70, 3.00, IF(BB11>=65, 2.50, IF(BB11>=60, 2.00, IF(BB11>=55, 1.50, IF(BB11>=50, 1.00, 0.00))))))) | BD11: =IF(BB11>=91,"A",IF(BB11>=81,"B+",IF(BB11>=70,"B",IF(BB11>=65,"C+",IF(BB11>=60,"C",IF(BB11>=55,"D+",IF(BB11>=50,"D","F"))))))) | BE11: =IF(BC11>90,"A",IF(BC11>80,"B+",IF(BC11>69,"B",IF(BC11>64,"C+",IF(BC11>59,"C",IF(BC11>54,"D+",IF(BC11>49,"D",IF(BC11>=0,"F")))))))) -> F | BF11: =IF(BE11>=91, 4.00, IF(BE11>=81, 3.50, IF(BE11>=70, 3.00, IF(BE11>=65, 2.50, IF(BE11>=60, 2.00, IF(BE11>=55, 1.50, IF(BE11>=50, 1.00, 0.00))))))) | BG11: =IF(BE11>=91,"A",IF(BE11>=81,"B+",IF(BE11>=70,"B",IF(BE11>=65,"C+",IF(BE11>=60,"C",IF(BE11>=55,"D+",IF(BE11>=50,"D","F"))))))) | BH11: =IF(BF11>90,"A",IF(BF11>80,"B+",IF(BF11>69,"B",IF(BF11>64,"C+",IF(BF11>59,"C",IF(BF11>54,"D+",IF(BF11>49,"D",IF(BF11>=0,"F")))))))) -> F | BI11: =IF(BH11>=91, 4.00, IF(BH11>=81, 3.50, IF(BH11>=70, 3.00, IF(BH11>=65, 2.50, IF(BH11>=60, 2.00, IF(BH11>=55, 1.50, IF(BH11>=50, 1.00, 0.00))))))) | BJ11: =IF(BH11>=91,"A",IF(BH11>=81,"B+",IF(BH11>=70,"B",IF(BH11>=65,"C+",IF(BH11>=60,"C",IF(BH11>=55,"D+",IF(BH11>=50,"D","F"))))))) | BK11: =IF(BI11>90,"A",IF(BI11>80,"B+",IF(BI11>69,"B",IF(BI11>64,"C+",IF(BI11>59,"C",IF(BI11>54,"D+",IF(BI11>49,"D",IF(BI11>=0,"F")))))))) -> F | BL11: =IF(BK11>=91, 4.00, IF(BK11>=81, 3.50, IF(BK11>=70, 3.00, IF(BK11>=65, 2.50, IF(BK11>=60, 2.00, IF(BK11>=55, 1.50, IF(BK11>=50, 1.00, 0.00))))))) | BM11: =IF(BK11>=91,"A",IF(BK11>=81,"B+",IF(BK11>=70,"B",IF(BK11>=65,"C+",IF(BK11>=60,"C",IF(BK11>=55,"D+",IF(BK11>=50,"D","F"))))))) | BN11: =IF(BL11>90,"A",IF(BL11>80,"B+",IF(BL11>69,"B",IF(BL11>64,"C+",IF(BL11>59,"C",IF(BL11>54,"D+",IF(BL11>49,"D",IF(BL11>=0,"F")))))))) -> F | BO11: =IF(BN11>=91, 4.00, IF(BN11>=81, 3.50, IF(BN11>=70, 3.00, IF(BN11>=65, 2.50, IF(BN11>=60, 2.00, IF(BN11>=55, 1.50, IF(BN11>=50, 1.00, 0.00))))))) | BP11: =IF(BN11>=91,"A",IF(BN11>=81,"B+",IF(BN11>=70,"B",IF(BN11>=65,"C+",IF(BN11>=60,"C",IF(BN11>=55,"D+",IF(BN11>=50,"D","F"))))))) | BQ11: =ROUND((AN11*3+AQ11*2+AT11*1+AW11*2+AZ11*1+BC11*1+BF11*2+BI11*2+BL11*2+BO11*3)/19, 2) | BR11: 45 | BS11: =IF(BR11>90,"4.00",IF(BR11>80,"3.50",IF(BR11>69,"3.00",IF(BR11>64,"2.50",IF(BR11>59,"2.00",IF(BR11>54,"1.50",IF(BR11>49,"1.00","0.00"))))))) -> 0.00 | BT11: =IF(BR11>90,"A",IF(BR11>80,"B+",IF(BR11>69,"B",IF(BR11>64,"C+",IF(BR11>59,"C",IF(BR11>54,"D+",IF(BR11>49,"D",IF(BR11>=0,"F")))))))) -> F | BU11: 62 | BV11: =IF(BU11>90,"4.00",IF(BU11>80,"3.50",IF(BU11>69,"3.00",IF(BU11>64,"2.50",IF(BU11>59,"2.00",IF(BU11>54,"1.50",IF(BU11>49,"1.00","0.00"))))))) -> 2.00 | BW11: =IF(BU11>90,"A",IF(BU11>80,"B+",IF(BU11>69,"B",IF(BU11>64,"C+",IF(BU11>59,"C",IF(BU11>54,"D+",IF(BU11>49,"D",IF(BU11>=0,"F")))))))) -> C | BX11: =(AX11*3+BA11*2+BD11*1+BG11*2+BJ11*1+BM11*1+BP11*2+BS11*2+BV11*2)/(3+2+1+2+1+1+2+2+2) -> 0.5625 | BY11: =(AL11+BX11)/2 -> 0.95772059 | BZ11: =RANK(BY11,$BY$7:BY38) -> 28
A12: 6 | B12: 125N0615/23 | C12: ນາງ | D12: ທິບພະກອນ | E12: ຫຼວງລາດ | F12: Ms.Thipphakone | G12: LOUANGRATH | H12: 37681 | I12: ນະຄອນຫຼວງວຽງຈັນ | J12: 1 | K12: 83 | L12: =IF(K12>=91, 4.00, IF(K12>=81, 3.50, IF(K12>=70, 3.00, IF(K12>=65, 2.50, IF(K12>=60, 2.00, IF(K12>=55, 1.50, IF(K12>=50, 1.00, 0.00))))))) | M12: =IF(K12>=91,"A",IF(K12>=81,"B+",IF(K12>=70,"B",IF(K12>=65,"C+",IF(K12>=60,"C",IF(K12>=55,"D+",IF(K12>=50,"D","F"))))))) | N12: 96 | O12: =IF(N12>=91, 4.00, IF(N12>=81, 3.50, IF(N12>=70, 3.00, IF(N12>=65, 2.50, IF(N12>=60, 2.00, IF(N12>=55, 1.50, IF(N12>=50, 1.00, 0.00))))))) | P12: =IF(N12>=91,"A",IF(N12>=81,"B+",IF(N12>=70,"B",IF(N12>=65,"C+",IF(N12>=60,"C",IF(N12>=55,"D+",IF(N12>=50,"D","F"))))))) | Q12: 97 | R12: =IF(Q12>=91, 4.00, IF(Q12>=81, 3.50, IF(Q12>=70, 3.00, IF(Q12>=65, 2.50, IF(Q12>=60, 2.00, IF(Q12>=55, 1.50, IF(Q12>=50, 1.00, 0.00))))))) | S12: =IF(Q12>=91,"A",IF(Q12>=81,"B+",IF(Q12>=70,"B",IF(Q12>=65,"C+",IF(Q12>=60,"C",IF(Q12>=55,"D+",IF(Q12>=50,"D","F"))))))) | T12: 78 | U12: =IF(T12>=91, 4.00, IF(T12>=81, 3.50, IF(T12>=70, 3.00, IF(T12>=65, 2.50, IF(T12>=60, 2.00, IF(T12>=55, 1.50, IF(T12>=50, 1.00, 0.00))))))) | V12: =IF(T12>=91,"A",IF(T12>=81,"B+",IF(T12>=70,"B",IF(T12>=65,"C+",IF(T12>=60,"C",IF(T12>=55,"D+",IF(T12>=50,"D","F"))))))) | W12: 73 | X12: =IF(W12>=91, 4.00, IF(W12>=81, 3.50, IF(W12>=70, 3.00, IF(W12>=65, 2.50, IF(W12>=60, 2.00, IF(W12>=55, 1.50, IF(W12>=50, 1.00, 0.00))))))) | Y12: =IF(W12>=91,"A",IF(W12>=81,"B+",IF(W12>=70,"B",IF(W12>=65,"C+",IF(W12>=60,"C",IF(W12>=55,"D+",IF(W12>=50,"D","F"))))))) | Z12: 92.52 | AA12: =IF(Z12>=91, 4.00, IF(Z12>=81, 3.50, IF(Z12>=70, 3.00, IF(Z12>=65, 2.50, IF(Z12>=60, 2.00, IF(Z12>=55, 1.50, IF(Z12>=50, 1.00, 0.00))))))) | AB12: =IF(Z12>=91,"A",IF(Z12>=81,"B+",IF(Z12>=70,"B",IF(Z12>=65,"C+",IF(Z12>=60,"C",IF(Z12>=55,"D+",IF(Z12>=50,"D","F"))))))) | AC12: 86.5 | AD12: =IF(AC12>=91, 4.00, IF(AC12>=81, 3.50, IF(AC12>=70, 3.00, IF(AC12>=65, 2.50, IF(AC12>=60, 2.00, IF(AC12>=55, 1.50, IF(AC12>=50, 1.00, 0.00))))))) | AE12: =IF(AC12>=91,"A",IF(AC12>=81,"B+",IF(AC12>=70,"B",IF(AC12>=65,"C+",IF(AC12>=60,"C",IF(AC12>=55,"D+",IF(AC12>=50,"D","F"))))))) | AF12: 91 | AG12: =IF(AF12>=91, 4.00, IF(AF12>=81, 3.50, IF(AF12>=70, 3.00, IF(AF12>=65, 2.50, IF(AF12>=60, 2.00, IF(AF12>=55, 1.50, IF(AF12>=50, 1.00, 0.00))))))) | AH12: =IF(AF12>=91,"A",IF(AF12>=81,"B+",IF(AF12>=70,"B",IF(AF12>=65,"C+",IF(AF12>=60,"C",IF(AF12>=55,"D+",IF(AF12>=50,"D","F"))))))) | AI12: 86 | AJ12: =IF(AI12>=91, 4.00, IF(AI12>=81, 3.50, IF(AI12>=70, 3.00, IF(AI12>=65, 2.50, IF(AI12>=60, 2.00, IF(AI12>=55, 1.50, IF(AI12>=50, 1.00, 0.00))))))) | AK12: =IF(AI12>=91,"A",IF(AI12>=81,"B+",IF(AI12>=70,"B",IF(AI12>=65,"C+",IF(AI12>=60,"C",IF(AI12>=55,"D+",IF(AI12>=50,"D","F"))))))) | AL12: =ROUND((L12*3+O12*2+R12*1+U12*2+X12*1+AA12*2+AD12*2+AG12*2+AJ12*2)/17, 2) | AM12: 87 | AN12: =IF(AM12>=91, 4.00, IF(AM12>=81, 3.50, IF(AM12>=70, 3.00, IF(AM12>=65, 2.50, IF(AM12>=60, 2.00, IF(AM12>=55, 1.50, IF(AM12>=50, 1.00, 0.00))))))) | AO12: =IF(AM12>=91,"A",IF(AM12>=81,"B+",IF(AM12>=70,"B",IF(AM12>=65,"C+",IF(AM12>=60,"C",IF(AM12>=55,"D+",IF(AM12>=50,"D","F"))))))) | AP12: ນາງ | AQ12: =IF(AP12>=91, 4.00, IF(AP12>=81, 3.50, IF(AP12>=70, 3.00, IF(AP12>=65, 2.50, IF(AP12>=60, 2.00, IF(AP12>=55, 1.50, IF(AP12>=50, 1.00, 0.00))))))) | AR12: =IF(AP12>=91,"A",IF(AP12>=81,"B+",IF(AP12>=70,"B",IF(AP12>=65,"C+",IF(AP12>=60,"C",IF(AP12>=55,"D+",IF(AP12>=50,"D","F"))))))) | AS12: Ms.Thipphakone | AT12: =IF(AS12>=91, 4.00, IF(AS12>=81, 3.50, IF(AS12>=70, 3.00, IF(AS12>=65, 2.50, IF(AS12>=60, 2.00, IF(AS12>=55, 1.50, IF(AS12>=50, 1.00, 0.00))))))) | AU12: =IF(AS12>=91,"A",IF(AS12>=81,"B+",IF(AS12>=70,"B",IF(AS12>=65,"C+",IF(AS12>=60,"C",IF(AS12>=55,"D+",IF(AS12>=50,"D","F"))))))) | AV12: ນະຄອນຫຼວງວຽງຈັນ | AW12: =IF(AV12>=91, 4.00, IF(AV12>=81, 3.50, IF(AV12>=70, 3.00, IF(AV12>=65, 2.50, IF(AV12>=60, 2.00, IF(AV12>=55, 1.50, IF(AV12>=50, 1.00, 0.00))))))) | AX12: =IF(AV12>=91,"A",IF(AV12>=81,"B+",IF(AV12>=70,"B",IF(AV12>=65,"C+",IF(AV12>=60,"C",IF(AV12>=55,"D+",IF(AV12>=50,"D","F"))))))) | AY12: =IF(AW12>90,"A",IF(AW12>80,"B+",IF(AW12>69,"B",IF(AW12>64,"C+",IF(AW12>59,"C",IF(AW12>54,"D+",IF(AW12>49,"D",IF(AW12>=0,"F")))))))) -> B+ | AZ12: =IF(AY12>=91, 4.00, IF(AY12>=81, 3.50, IF(AY12>=70, 3.00, IF(AY12>=65, 2.50, IF(AY12>=60, 2.00, IF(AY12>=55, 1.50, IF(AY12>=50, 1.00, 0.00))))))) | BA12: =IF(AY12>=91,"A",IF(AY12>=81,"B+",IF(AY12>=70,"B",IF(AY12>=65,"C+",IF(AY12>=60,"C",IF(AY12>=55,"D+",IF(AY12>=50,"D","F"))))))) | BB12: =IF(AZ12>90,"A",IF(AZ12>80,"B+",IF(AZ12>69,"B",IF(AZ12>64,"C+",IF(AZ12>59,"C",IF(AZ12>54,"D+",IF(AZ12>49,"D",IF(AZ12>=0,"F")))))))) -> B+ | BC12: =IF(BB12>=91, 4.00, IF(BB12>=81, 3.50, IF(BB12>=70, 3.00, IF(BB12>=65, 2.50, IF(BB12>=60, 2.00, IF(BB12>=55, 1.50, IF(BB12>=50, 1.00, 0.00))))))) | BD12: =IF(BB12>=91,"A",IF(BB12>=81,"B+",IF(BB12>=70,"B",IF(BB12>=65,"C+",IF(BB12>=60,"C",IF(BB12>=55,"D+",IF(BB12>=50,"D","F"))))))) | BE12: =IF(BC12>90,"A",IF(BC12>80,"B+",IF(BC12>69,"B",IF(BC12>64,"C+",IF(BC12>59,"C",IF(BC12>54,"D+",IF(BC12>49,"D",IF(BC12>=0,"F")))))))) -> B+ | BF12: =IF(BE12>=91, 4.00, IF(BE12>=81, 3.50, IF(BE12>=70, 3.00, IF(BE12>=65, 2.50, IF(BE12>=60, 2.00, IF(BE12>=55, 1.50, IF(BE12>=50, 1.00, 0.00))))))) | BG12: =IF(BE12>=91,"A",IF(BE12>=81,"B+",IF(BE12>=70,"B",IF(BE12>=65,"C+",IF(BE12>=60,"C",IF(BE12>=55,"D+",IF(BE12>=50,"D","F"))))))) | BH12: =IF(BF12>90,"A",IF(BF12>80,"B+",IF(BF12>69,"B",IF(BF12>64,"C+",IF(BF12>59,"C",IF(BF12>54,"D+",IF(BF12>49,"D",IF(BF12>=0,"F")))))))) -> B+ | BI12: =IF(BH12>=91, 4.00, IF(BH12>=81, 3.50, IF(BH12>=70, 3.00, IF(BH12>=65, 2.50, IF(BH12>=60, 2.00, IF(BH12>=55, 1.50, IF(BH12>=50, 1.00, 0.00))))))) | BJ12: =IF(BH12>=91,"A",IF(BH12>=81,"B+",IF(BH12>=70,"B",IF(BH12>=65,"C+",IF(BH12>=60,"C",IF(BH12>=55,"D+",IF(BH12>=50,"D","F"))))))) | BK12: =IF(BI12>90,"A",IF(BI12>80,"B+",IF(BI12>69,"B",IF(BI12>64,"C+",IF(BI12>59,"C",IF(BI12>54,"D+",IF(BI12>49,"D",IF(BI12>=0,"F")))))))) -> B+ | BL12: =IF(BK12>=91, 4.00, IF(BK12>=81, 3.50, IF(BK12>=70, 3.00, IF(BK12>=65, 2.50, IF(BK12>=60, 2.00, IF(BK12>=55, 1.50, IF(BK12>=50, 1.00, 0.00))))))) | BM12: =IF(BK12>=91,"A",IF(BK12>=81,"B+",IF(BK12>=70,"B",IF(BK12>=65,"C+",IF(BK12>=60,"C",IF(BK12>=55,"D+",IF(BK12>=50,"D","F"))))))) | BN12: =IF(BL12>90,"A",IF(BL12>80,"B+",IF(BL12>69,"B",IF(BL12>64,"C+",IF(BL12>59,"C",IF(BL12>54,"D+",IF(BL12>49,"D",IF(BL12>=0,"F")))))))) -> A | BO12: =IF(BN12>=91, 4.00, IF(BN12>=81, 3.50, IF(BN12>=70, 3.00, IF(BN12>=65, 2.50, IF(BN12>=60, 2.00, IF(BN12>=55, 1.50, IF(BN12>=50, 1.00, 0.00))))))) | BP12: =IF(BN12>=91,"A",IF(BN12>=81,"B+",IF(BN12>=70,"B",IF(BN12>=65,"C+",IF(BN12>=60,"C",IF(BN12>=55,"D+",IF(BN12>=50,"D","F"))))))) | BQ12: =ROUND((AN12*3+AQ12*2+AT12*1+AW12*2+AZ12*1+BC12*1+BF12*2+BI12*2+BL12*2+BO12*3)/19, 2) | BR12: 88 | BS12: =IF(BR12>90,"4.00",IF(BR12>80,"3.50",IF(BR12>69,"3.00",IF(BR12>64,"2.50",IF(BR12>59,"2.00",IF(BR12>54,"1.50",IF(BR12>49,"1.00","0.00"))))))) -> 3.50 | BT12: =IF(BR12>90,"A",IF(BR12>80,"B+",IF(BR12>69,"B",IF(BR12>64,"C+",IF(BR12>59,"C",IF(BR12>54,"D+",IF(BR12>49,"D",IF(BR12>=0,"F")))))))) -> B+ | BU12: 75 | BV12: =IF(BU12>90,"4.00",IF(BU12>80,"3.50",IF(BU12>69,"3.00",IF(BU12>64,"2.50",IF(BU12>59,"2.00",IF(BU12>54,"1.50",IF(BU12>49,"1.00","0.00"))))))) -> 3.00 | BW12: =IF(BU12>90,"A",IF(BU12>80,"B+",IF(BU12>69,"B",IF(BU12>64,"C+",IF(BU12>59,"C",IF(BU12>54,"D+",IF(BU12>49,"D",IF(BU12>=0,"F")))))))) -> B | BX12: =(AX12*3+BA12*2+BD12*1+BG12*2+BJ12*1+BM12*1+BP12*2+BS12*2+BV12*2)/(3+2+1+2+1+1+2+2+2) -> 3.40625 | BY12: =(AL12+BX12)/2 -> 3.3943015 | BZ12: =RANK(BY12,$BY$7:BY40) -> 3
A13: 7 | B13: 125N0616/23 | C13: ນາງ | D13: ວິລັດດາ | E13: ເພຍຄຳ | F13: Ms.Vilatda | G13: PHIAKHAM | H13: 28/08/2005 | I13: ບໍລິຄຳໄຊ | J13: 1 | K13: 80 | L13: =IF(K13>=91, 4.00, IF(K13>=81, 3.50, IF(K13>=70, 3.00, IF(K13>=65, 2.50, IF(K13>=60, 2.00, IF(K13>=55, 1.50, IF(K13>=50, 1.00, 0.00))))))) | M13: =IF(K13>=91,"A",IF(K13>=81,"B+",IF(K13>=70,"B",IF(K13>=65,"C+",IF(K13>=60,"C",IF(K13>=55,"D+",IF(K13>=50,"D","F"))))))) | N13: 91 | O13: =IF(N13>=91, 4.00, IF(N13>=81, 3.50, IF(N13>=70, 3.00, IF(N13>=65, 2.50, IF(N13>=60, 2.00, IF(N13>=55, 1.50, IF(N13>=50, 1.00, 0.00))))))) | P13: =IF(N13>=91,"A",IF(N13>=81,"B+",IF(N13>=70,"B",IF(N13>=65,"C+",IF(N13>=60,"C",IF(N13>=55,"D+",IF(N13>=50,"D","F"))))))) | Q13: 93 | R13: =IF(Q13>=91, 4.00, IF(Q13>=81, 3.50, IF(Q13>=70, 3.00, IF(Q13>=65, 2.50, IF(Q13>=60, 2.00, IF(Q13>=55, 1.50, IF(Q13>=50, 1.00, 0.00))))))) | S13: =IF(Q13>=91,"A",IF(Q13>=81,"B+",IF(Q13>=70,"B",IF(Q13>=65,"C+",IF(Q13>=60,"C",IF(Q13>=55,"D+",IF(Q13>=50,"D","F"))))))) | T13: 65 | U13: =IF(T13>=91, 4.00, IF(T13>=81, 3.50, IF(T13>=70, 3.00, IF(T13>=65, 2.50, IF(T13>=60, 2.00, IF(T13>=55, 1.50, IF(T13>=50, 1.00, 0.00))))))) | V13: =IF(T13>=91,"A",IF(T13>=81,"B+",IF(T13>=70,"B",IF(T13>=65,"C+",IF(T13>=60,"C",IF(T13>=55,"D+",IF(T13>=50,"D","F"))))))) | W13: 70 | X13: =IF(W13>=91, 4.00, IF(W13>=81, 3.50, IF(W13>=70, 3.00, IF(W13>=65, 2.50, IF(W13>=60, 2.00, IF(W13>=55, 1.50, IF(W13>=50, 1.00, 0.00))))))) | Y13: =IF(W13>=91,"A",IF(W13>=81,"B+",IF(W13>=70,"B",IF(W13>=65,"C+",IF(W13>=60,"C",IF(W13>=55,"D+",IF(W13>=50,"D","F"))))))) | Z13: 85.27 | AA13: =IF(Z13>=91, 4.00, IF(Z13>=81, 3.50, IF(Z13>=70, 3.00, IF(Z13>=65, 2.50, IF(Z13>=60, 2.00, IF(Z13>=55, 1.50, IF(Z13>=50, 1.00, 0.00))))))) | AB13: =IF(Z13>=91,"A",IF(Z13>=81,"B+",IF(Z13>=70,"B",IF(Z13>=65,"C+",IF(Z13>=60,"C",IF(Z13>=55,"D+",IF(Z13>=50,"D","F"))))))) | AC13: 81 | AD13: =IF(AC13>=91, 4.00, IF(AC13>=81, 3.50, IF(AC13>=70, 3.00, IF(AC13>=65, 2.50, IF(AC13>=60, 2.00, IF(AC13>=55, 1.50, IF(AC13>=50, 1.00, 0.00))))))) | AE13: =IF(AC13>=91,"A",IF(AC13>=81,"B+",IF(AC13>=70,"B",IF(AC13>=65,"C+",IF(AC13>=60,"C",IF(AC13>=55,"D+",IF(AC13>=50,"D","F"))))))) | AF13: 80 | AG13: =IF(AF13>=91, 4.00, IF(AF13>=81, 3.50, IF(AF13>=70, 3.00, IF(AF13>=65, 2.50, IF(AF13>=60, 2.00, IF(AF13>=55, 1.50, IF(AF13>=50, 1.00, 0.00))))))) | AH13: =IF(AF13>=91,"A",IF(AF13>=81,"B+",IF(AF13>=70,"B",IF(AF13>=65,"C+",IF(AF13>=60,"C",IF(AF13>=55,"D+",IF(AF13>=50,"D","F"))))))) | AI13: 87 | AJ13: =IF(AI13>=91, 4.00, IF(AI13>=81, 3.50, IF(AI13>=70, 3.00, IF(AI13>=65, 2.50, IF(AI13>=60, 2.00, IF(AI13>=55, 1.50, IF(AI13>=50, 1.00, 0.00))))))) | AK13: =IF(AI13>=91,"A",IF(AI13>=81,"B+",IF(AI13>=70,"B",IF(AI13>=65,"C+",IF(AI13>=60,"C",IF(AI13>=55,"D+",IF(AI13>=50,"D","F"))))))) | AL13: =ROUND((L13*3+O13*2+R13*1+U13*2+X13*1+AA13*2+AD13*2+AG13*2+AJ13*2)/17, 2) | AM13: 90 | AN13: =IF(AM13>=91, 4.00, IF(AM13>=81, 3.50, IF(AM13>=70, 3.00, IF(AM13>=65, 2.50, IF(AM13>=60, 2.00, IF(AM13>=55, 1.50, IF(AM13>=50, 1.00, 0.00))))))) | AO13: =IF(AM13>=91,"A",IF(AM13>=81,"B+",IF(AM13>=70,"B",IF(AM13>=65,"C+",IF(AM13>=60,"C",IF(AM13>=55,"D+",IF(AM13>=50,"D","F"))))))) | AP13: ນາງ | AQ13: =IF(AP13>=91, 4.00, IF(AP13>=81, 3.50, IF(AP13>=70, 3.00, IF(AP13>=65, 2.50, IF(AP13>=60, 2.00, IF(AP13>=55, 1.50, IF(AP13>=50, 1.00, 0.00))))))) | AR13: =IF(AP13>=91,"A",IF(AP13>=81,"B+",IF(AP13>=70,"B",IF(AP13>=65,"C+",IF(AP13>=60,"C",IF(AP13>=55,"D+",IF(AP13>=50,"D","F"))))))) | AS13: Ms.Vilatda | AT13: =IF(AS13>=91, 4.00, IF(AS13>=81, 3.50, IF(AS13>=70, 3.00, IF(AS13>=65, 2.50, IF(AS13>=60, 2.00, IF(AS13>=55, 1.50, IF(AS13>=50, 1.00, 0.00))))))) | AU13: =IF(AS13>=91,"A",IF(AS13>=81,"B+",IF(AS13>=70,"B",IF(AS13>=65,"C+",IF(AS13>=60,"C",IF(AS13>=55,"D+",IF(AS13>=50,"D","F"))))))) | AV13: ບໍລິຄຳໄຊ | AW13: =IF(AV13>=91, 4.00, IF(AV13>=81, 3.50, IF(AV13>=70, 3.00, IF(AV13>=65, 2.50, IF(AV13>=60, 2.00, IF(AV13>=55, 1.50, IF(AV13>=50, 1.00, 0.00))))))) | AX13: =IF(AV13>=91,"A",IF(AV13>=81,"B+",IF(AV13>=70,"B",IF(AV13>=65,"C+",IF(AV13>=60,"C",IF(AV13>=55,"D+",IF(AV13>=50,"D","F"))))))) | AY13: =IF(AW13>90,"A",IF(AW13>80,"B+",IF(AW13>69,"B",IF(AW13>64,"C+",IF(AW13>59,"C",IF(AW13>54,"D+",IF(AW13>49,"D",IF(AW13>=0,"F")))))))) -> B+ | AZ13: =IF(AY13>=91, 4.00, IF(AY13>=81, 3.50, IF(AY13>=70, 3.00, IF(AY13>=65, 2.50, IF(AY13>=60, 2.00, IF(AY13>=55, 1.50, IF(AY13>=50, 1.00, 0.00))))))) | BA13: =IF(AY13>=91,"A",IF(AY13>=81,"B+",IF(AY13>=70,"B",IF(AY13>=65,"C+",IF(AY13>=60,"C",IF(AY13>=55,"D+",IF(AY13>=50,"D","F"))))))) | BB13: =IF(AZ13>90,"A",IF(AZ13>80,"B+",IF(AZ13>69,"B",IF(AZ13>64,"C+",IF(AZ13>59,"C",IF(AZ13>54,"D+",IF(AZ13>49,"D",IF(AZ13>=0,"F")))))))) -> A | BC13: =IF(BB13>=91, 4.00, IF(BB13>=81, 3.50, IF(BB13>=70, 3.00, IF(BB13>=65, 2.50, IF(BB13>=60, 2.00, IF(BB13>=55, 1.50, IF(BB13>=50, 1.00, 0.00))))))) | BD13: =IF(BB13>=91,"A",IF(BB13>=81,"B+",IF(BB13>=70,"B",IF(BB13>=65,"C+",IF(BB13>=60,"C",IF(BB13>=55,"D+",IF(BB13>=50,"D","F"))))))) | BE13: =IF(BC13>90,"A",IF(BC13>80,"B+",IF(BC13>69,"B",IF(BC13>64,"C+",IF(BC13>59,"C",IF(BC13>54,"D+",IF(BC13>49,"D",IF(BC13>=0,"F")))))))) -> A | BF13: =IF(BE13>=91, 4.00, IF(BE13>=81, 3.50, IF(BE13>=70, 3.00, IF(BE13>=65, 2.50, IF(BE13>=60, 2.00, IF(BE13>=55, 1.50, IF(BE13>=50, 1.00, 0.00))))))) | BG13: =IF(BE13>=91,"A",IF(BE13>=81,"B+",IF(BE13>=70,"B",IF(BE13>=65,"C+",IF(BE13>=60,"C",IF(BE13>=55,"D+",IF(BE13>=50,"D","F"))))))) | BH13: =IF(BF13>90,"A",IF(BF13>80,"B+",IF(BF13>69,"B",IF(BF13>64,"C+",IF(BF13>59,"C",IF(BF13>54,"D+",IF(BF13>49,"D",IF(BF13>=0,"F")))))))) -> A | BI13: =IF(BH13>=91, 4.00, IF(BH13>=81, 3.50, IF(BH13>=70, 3.00, IF(BH13>=65, 2.50, IF(BH13>=60, 2.00, IF(BH13>=55, 1.50, IF(BH13>=50, 1.00, 0.00))))))) | BJ13: =IF(BH13>=91,"A",IF(BH13>=81,"B+",IF(BH13>=70,"B",IF(BH13>=65,"C+",IF(BH13>=60,"C",IF(BH13>=55,"D+",IF(BH13>=50,"D","F"))))))) | BK13: =IF(BI13>90,"A",IF(BI13>80,"B+",IF(BI13>69,"B",IF(BI13>64,"C+",IF(BI13>59,"C",IF(BI13>54,"D+",IF(BI13>49,"D",IF(BI13>=0,"F")))))))) -> A | BL13: =IF(BK13>=91, 4.00, IF(BK13>=81, 3.50, IF(BK13>=70, 3.00, IF(BK13>=65, 2.50, IF(BK13>=60, 2.00, IF(BK13>=55, 1.50, IF(BK13>=50, 1.00, 0.00))))))) | BM13: =IF(BK13>=91,"A",IF(BK13>=81,"B+",IF(BK13>=70,"B",IF(BK13>=65,"C+",IF(BK13>=60,"C",IF(BK13>=55,"D+",IF(BK13>=50,"D","F"))))))) | BN13: =IF(BL13>90,"A",IF(BL13>80,"B+",IF(BL13>69,"B",IF(BL13>64,"C+",IF(BL13>59,"C",IF(BL13>54,"D+",IF(BL13>49,"D",IF(BL13>=0,"F")))))))) -> A | BO13: =IF(BN13>=91, 4.00, IF(BN13>=81, 3.50, IF(BN13>=70, 3.00, IF(BN13>=65, 2.50, IF(BN13>=60, 2.00, IF(BN13>=55, 1.50, IF(BN13>=50, 1.00, 0.00))))))) | BP13: =IF(BN13>=91,"A",IF(BN13>=81,"B+",IF(BN13>=70,"B",IF(BN13>=65,"C+",IF(BN13>=60,"C",IF(BN13>=55,"D+",IF(BN13>=50,"D","F"))))))) | BQ13: =ROUND((AN13*3+AQ13*2+AT13*1+AW13*2+AZ13*1+BC13*1+BF13*2+BI13*2+BL13*2+BO13*3)/19, 2) | BR13: 71 | BS13: =IF(BR13>90,"4.00",IF(BR13>80,"3.50",IF(BR13>69,"3.00",IF(BR13>64,"2.50",IF(BR13>59,"2.00",IF(BR13>54,"1.50",IF(BR13>49,"1.00","0.00"))))))) -> 3.00 | BT13: =IF(BR13>90,"A",IF(BR13>80,"B+",IF(BR13>69,"B",IF(BR13>64,"C+",IF(BR13>59,"C",IF(BR13>54,"D+",IF(BR13>49,"D",IF(BR13>=0,"F")))))))) -> B | BU13: 79 | BV13: =IF(BU13>90,"4.00",IF(BU13>80,"3.50",IF(BU13>69,"3.00",IF(BU13>64,"2.50",IF(BU13>59,"2.00",IF(BU13>54,"1.50",IF(BU13>49,"1.00","0.00"))))))) -> 3.00 | BW13: =IF(BU13>90,"A",IF(BU13>80,"B+",IF(BU13>69,"B",IF(BU13>64,"C+",IF(BU13>59,"C",IF(BU13>54,"D+",IF(BU13>49,"D",IF(BU13>=0,"F")))))))) -> B | BX13: =(AX13*3+BA13*2+BD13*1+BG13*2+BJ13*1+BM13*1+BP13*2+BS13*2+BV13*2)/(3+2+1+2+1+1+2+2+2) -> 3.53125 | BY13: =(AL13+BX13)/2 -> 3.3097426 | BZ13: =RANK(BY13,$BY$7:BY41) -> 7
